Workbook
Name days_year: 'calc'!$C$6
Name work_days: 'calc'!$C$7
Name days_week: 'calc'!$C$8
Name months: 'calc'!$C$9
Name quarters: 'calc'!$C$10
Name weeks_year: 'calc'!$C$11
Name nominal_hours: 'calc'!$C$12
Name work_months: 'calc'!$C$13
Name vacation_cal: 'calc'!$C$14
Name vacation_work: 'calc'!$C$15
Name sick_cal: 'calc'!$C$16
Name sick_work: 'calc'!$C$17
Name eff_hours: 'calc'!$C$18
Name work_time: 'calc'!$C$21
Name net_days: 'calc'!$C$22
Name net_time: 'calc'!$C$23
Name net_weeks: 'calc'!$C$24
Name promo_per_day: 'calc'!$C$25
Name promo_time: 'calc'!$C$26
Name acc_mode: 'calc'!$C$27
Name acc_per_quarter: 'calc'!$C$28
Name accounting_time: 'calc'!$C$29
Name side_time: 'calc'!$C$30
Name pool_gross: 'calc'!$C$31
Name fm_on: 'calc'!$C$32
Name fm_pct: 'calc'!$C$33
Name fm_time: 'calc'!$C$34
Name fm_week: 'calc'!$C$35
Name project_pool: 'calc'!$C$36
Name post_ratio: 'calc'!$C$39
Name profile_multiplier: 'calc'!$C$40
Name client_time: 'calc'!$C$41
Name shoot_duration: 'calc'!$C$42
Name week_target: 'calc'!$C$43
Name shoot_auto: 'calc'!$C$44
Name project_time: 'calc'!$C$45
Name projects_year: 'calc'!$C$46
Name projects_month: 'calc'!$C$47
Name projects_week: 'calc'!$C$48
Name shooting_time: 'calc'!$C$49
Name shooting_month: 'calc'!$C$50
Name shooting_week: 'calc'!$C$51
Name post_time: 'calc'!$C$52
Name core_time: 'calc'!$C$53
Name client_total: 'calc'!$C$54
Name ops_per_shoot: 'calc'!$C$55
Name income_month: 'calc'!$C$58
Name target_income: 'calc'!$C$59
Name current_rate: 'calc'!$C$60
Name ws_mode: 'calc'!$C$63
Name own_home: 'calc'!$C$64
Name home_rent: 'calc'!$C$65
Name home_util: 'calc'!$C$66
Name home_area: 'calc'!$C$67
Name cab_area: 'calc'!$C$68
Name cab_share: 'calc'!$C$69
Name office_rent: 'calc'!$C$70
Name office_util: 'calc'!$C$71
Name var_workspace: 'calc'!$C$72
Name edu_cost: 'calc'!$C$75

Sheet 00_Читать
A1: СЧЁТИКС · калькулятор стоимости часа
A2: Расчёт юнит-экономики для фотографов и видеографов. Обновлено 25 августа 2026.
A4: ИЗ ЧЕГО СОСТОИТ ПРОДУКТ — ЧЕТЫРЕ ФАЙЛА
A5: Файл | B5: Что это и где живёт
A6: Книга/Калькулятор_ставки_часа.xlsx | B6: ЭТА КНИГА, 30 листов: параметры, каталоги, расчёт, глоссарий, реестры. Источник понятий и сверка
A7: Веб/index.html | B7: СТРАНИЦА ВХОДА. Обложка; кто уже начинал — сразу в анкету
A8: Веб/calc.html | B8: АНКЕТА + ВЕСЬ РАСЧЁТ — функция calc(). Результат вынесен в отчёт
A9: Веб/report.html | B9: ПОЛНЫЙ ОТЧЁТ: 21 блок, справочник на 77 понятий, 8 таблиц детализации. Бесплатный; данные приходят из анкеты
A11: ОПОРНЫЕ ЛИСТЫ КНИГИ — 30 ЛИСТОВ
A12: Лист | B12: Назначение
A13: 00_Читать | B13: Этот лист — карта книги
A14: 01_Глоссарий | B14: Источник понятий: 125 строк
A15: calc | B15: 121 именованная величина. ГЛАВНЫЙ лист для правки цифр
A16: Состав | B16: Группировка параметров отчёта: ID из calc, наименование из глоссария, составные части по номерам. Заполняется по блокам
A17: 03_Каталоги | B17: Позиции форм: техника, ПО, реклама, банк
A18: 04_Итог / 05_Расчёт | B18: Свод по режиму и расчёт по семи налоговым режимам
A19: 06_Отчёт / 06b_Отчёт_полный | B19: Отчёт в книге; 06b — 46 показателей со сверкой с калькулятором
A20: 07_Интерфейс / 08_UI / 08c_Структура_отчёта | B20: Структура анкеты и отчёта
A21: 09_Тексты | B21: 514 надписей: ключ data-t → текст
A22: 09b_Методика_цифр / 09e_Как_считается | B22: Как посчитана каждая цифра отчёта
A23: 09c_Палитра / 09d_Логотип / 09g_Сокращения / 09h_Элементы | B23: Единый стиль записи и оформления
... A28: 28_Журнал_изменений | B28: Летопись модели
A30: ЧТО ГДЕ ПРАВИТЬ
A31: Задача | B31: Куда идти
A32: Поменять текст надписи | B32: 09_Тексты → найти по ключу data-t из HTML → колонка «Текст»
A33: Поменять цифру или формулу | B33: calc → колонка «Значение»
A34: Поменять цвет | B34: 09c_Палитра → HEX → тот же токен в :root обоих HTML
A35: Добавить оборудование | B35: 03_Каталоги → новая строка с кодом формы
A36: Изменить скидки, фонд, сертификаты | B36: 13b_Программа_лояльности → жёлтые ячейки
A38: ПЕРЕД ПУБЛИКАЦИЕЙ — ОБЯЗАТЕЛЬНО
A39: 1 | B39: YM_ID → номер счётчика Метрики (сейчас 0)
A40: 2 | B40: PAY_URL → ссылка оплаты (сейчас «#order»); возврат — report.html?paid=1
A41: 3 | B41: Выполнить З-039: публикационная копия без DEMO
A42: 4 | B42: Пройти путь целиком на телефоне и на компьютере
A44: Подробности — Документация/Подготовка к запуску/ и README.md в корне проекта.

Sheet 01_Глоссарий
A1: № | B1: Наименование | C1: ID | D1: Назначение | E1: Тип | F1: Определение
A1: 1 | B2: Маркер | C2: marker | D2: meta | E2: — | F2: Служебный параметр, который используется для обозначения принадлежности элемента или понятия к определённому типу, категории или назначению.
A2: 2 | B3: id в вёрстке | C3: id | D3: meta | E3: — | F3: Обозначение элемента на странице, по которому скрипт подставляет в него рассчитанное значение.
A3: 3 | B4: Служебное понятие | C4: meta | D4: meta | E4: marker | F4: Обозначение, описывающее устройство самого калькулятора, а не деятельность специалиста.
A4: 4 | B5: Пользовательское понятие | C5: user | D5: meta | E5: marker | F5: Понятие глоссария, предназначенное для публикации в пользовательском справочнике. Одновременно используется во внутренних расчётах, документации и связях проекта.
A5: 5 | B6: Параметр | C6: — | D6: meta | F6: Именованная величина, или характеристика со своим постоянным обозначением, которая используется в расчётах и на которую могут ссылаться формулы и другие параметры.
A6: 6 | B7: Назначение | C7: — | D7: meta | E7: marker | F7: Область использования элемента или понятия в структуре Счётикс и его проектной документации.
A7: 7 | B8: Тип | C8: — | D8: meta | E8: marker
A8: 8 | B9: Значение | D9: meta | F9: Конкретная величина или характеристика параметра, используемая калькулятором для отображения, расчёта или настройки результата.
A9: 9 | B10: Константа | C10: const | D10: meta | F10: Заранее установленное значение, которое используется в расчётах и не изменяется в зависимости от введённых пользователем данных.
A10: 10 | B11: Значение по умолчанию | C11: default | D11: meta | F11: Заранее установленное значение параметра, которое используется автоматически, если пользователь не указал другое значение.
A11: 11 | B12: Введённое значение | D12: meta | F12: Значение параметра, которое пользователь самостоятельно указал (выбрал из выпадающего списка, ввёл вручную или другим способом) или изменил вручную.
A12: 12 | B13: Тип значения | D13: meta | F13: Определяет, что означает значение параметра и как с ним работать в калькуляторе: процент, денежная сумма, время, количество, текст, выбор и т. д.
A13: 13 | B14: Расчётное значение (Формула) | D14: meta | F14: Значение, полученное в результате вычисления на основе других параметров.
A14: 14 | B15: Отображаемое значение | D15: meta | F15: Значение, которое выводится пользователю в интерфейсе и может отличаться от фактического значения параметра из-за форматирования, округления или способа представления.
A15: 15 | B16: Вводимые данные | C16: input_data | D16: meta | F16: Данные введенные пользователем вручную
A16: 16 | B17: Интерфейс | C17: ui | D17: meta | E17: marker | F17: Совокупность элементов, с которыми взаимодействует пользователь.
A17: 17 | B18: Страница | D18: meta | E18: ui | F18: Отдельный экран интерфейса, содержащий определённый набор элементов.
A18: 18 | B19: Анкета | D19: meta | E19: ui | F19: Часть интерфейса, предназначенная для последовательного ввода пользователем данных для расчета.
A19: 19 | B20: Отчёт | C20: report | D20: meta | E20: ui | F20: Часть интерфейса, предназначенная для представления результатов расчёта.
A20: 20 | B21: Главный экран | C21: hero | D21: meta | E21: ui | F21: Главный блок на странице
A21: 21 | B22: Раздел | C22: section | D22: meta | E22: ui | F22: Крупная часть анкеты, объединяющая несколько блоков.
A22: 22 | B23: Блок | C23: block | D23: meta | E23: ui | F23: Смысловая часть анкеты: один вопрос или группа связанных вопросов с общим заголовком.
A23: 23 | B24: Выпадающий список | C24: dropdown | D24: meta | E24: ui | F24: Выпадающий список с выбором одного варианта.
A24: 24 | B25: Поле с ручным вводом | D25: meta | E25: ui | F25: Элемент интерфейса, позволяющий пользователю самостоятельно ввести значение с клавиатуры в предусмотренное для этого поле.
A25: 25 | B26: Галочка | C26: checkbox | D26: meta | E26: ui | F26: Включает или выключает блок либо строку расчёта.
A26: 26 | B27: Обратная галочка | D27: meta | E27: ui | F27: Элемент интерфейса, позволяющий пользователю включить или отключить определённую опцию. Установка галочки активирует соответствующий блок или функцию, снятие галочки — отключает их.
A27: 27 | B28: Переключатель | C28: switch | D28: meta | E28: ui | F28: Параметр с выбором из нескольких вариантов, который меняет не только значение, но и сам ход расчёта.
A28: 28 | B29: Текстовый блок | C29: info_block | D29: meta | E29: ui | F29: Пояснительный текст без полей ввода.
A29: 29 | B30: Форма | C30: form | D30: meta | E30: ui | F30: Набор однотипных строк, которые пользователь заполняет списком.
A30: 30 | B31: Каталог | C31: cat_form, cat_year | D31: meta | E31: ui | F31: Список позиций формы вместе с ценой, сроком службы, периодом платежа и годовой суммой.
A31: 31 | B32: Таблица | D32: meta | E32: ui | F32: Элемент интерфейса, предназначенный для представления структурированной информации в виде строк и столбцов, где данные распределены по определённым категориям и показателям.
A32: 32 | B33: Шапка таблицы | C33: table_head | D33: meta | E33: ui | F33: Названия столбцов таблицы.
A33: 33 | B34: Строка таблицы | C34: table_row | D34: meta | E34: ui | F34: Одна строка, заполняемая пользователем.
A34: 34 | B35: Кнопка | C35: button | D35: meta | E35: ui | F35: Элемент интерфейса, предназначенный для выполнения определённого действия при нажатии.
A35: 35 | B36: Строка показателей | C36: report_row | D36: meta | E36: ui | F36: Три показателя в строку под главной плашкой.
A36: 36 | B37: Диаграмма | C37: chart_donut | D37: meta | E37: ui | F37: Кольцо с сегментами и легендой.
A37: 37 | B38: Книга | D38: meta | E38: ui | F38: Совокупность взаимосвязанных таблиц, объединённых в один файл или документ и предназначенных для совместного хранения, обработки и расчёта данных.
A38: 38 | B39: Лист книги | C39: list | D39: meta | E39: ui | F39: Отдельная страница книги с номером и назначением в названии.
A39: 39 | B40: Выручка | D40: user | F40: Общая сумма денежных средств, которую специалист получает от продажи своих услуг за определённый период, включая суммы, предназначенные для покрытия всех расходов и обязательных платежей, налогов, стоимости оборудования и его амортизации, банковских расходов, резервов на отпуск, развитие, обучение и другие предусмотренные расчётом затраты, а также доход специалиста.
...

Sheet calc
A1: 02 · ПАРАМЕТРЫ — каждая величина объявлена один раз, формулы записаны через ID
A2: Жёлтое — ввод пользователя. Оранжевое — ПЕРЕКЛЮЧАТЕЛЬ (выпадающий список). Зелёное — вычисляется. Серое — константа.
A4: 1 · КАЛЕНДАРЬ
A5: ID | B5: Название | C5: Значение | D5: Ед. | E5: Формула / как получено | F5: Тип | G5: Зависит от | H5: Источник / форма
A6: days_year | B6: Всего дней в году | C6: 365 | D6: дн | F6: const
A7: work_days | B7: Рабочих дней в году | C7: 247 | D7: дн | F7: const | H7: Произв. календарь РФ 2026
A8: days_week | B8: Рабочих дней в неделю | C8: 5 | D8: дн | F8: const
A9: months | B9: Месяцев в году | C9: 12 | D9: мес | F9: const
A10: quarters | B10: Кварталов в году | C10: 4 | D10: кв | F10: const
A11: weeks_year | B11: Всего недель в году | C11: =days_year/7 -> 52.142857 | D11: нед | E11: days_year/7 | F11: calc | G11: days_year
A12: nominal_hours | B12: Номинальных часов в дне | C12: 8 | D12: ч | F12: const | H12: ст. 91 ТК РФ
A13: work_months | B13: Рабочих месяцев в году | C13: 11 | D13: мес | F13: const | H13: СПРАВОЧНО, в расчёте не участвует
A14: vacation_cal | B14: Отпуск, календарных дней | C14: 28 | D14: дн | F14: const | H14: ст. 115 ТК РФ
A15: vacation_work | B15: Отпуск, рабочих дней | C15: 20 | D15: дн | F15: const
A16: sick_cal | B16: Больничный, календарных дней | C16: 10 | D16: дн | F16: const | H16: среднее за год
A17: sick_work | B17: Больничный, рабочих дней | C17: 8 | D17: дн | F17: const
A18: eff_hours | B18: Чистых (эффективных) часов в дне | C18: 7 | D18: ч | F18: const | H18: 8 минус час на перерывы
A19: 2 · ВРЕМЯ — иерархия по вашему определению
A20: ID | B20: Название | C20: Значение | D20: Ед. | E20: Формула / как получено | F20: Тип | G20: Зависит от | H20: Источник / форма
A21: work_time | B21: Рабочее время по календарю | C21: =work_days*nominal_hours -> 1976 | D21: ч/год | E21: work_days*nominal_hours | F21: calc | G21: work_days, nominal_hours | H21: 247 × 8. Справочно
A22: net_days | B22: Чистое рабочее время, дней | C22: =work_days-vacation_work-sick_work -> 219 | D22: дн/год | E22: work_days-vacation_work-sick_work | F22: calc | G22: work_days, vacation_work, sick_work
A23: net_time | B23: ЧИСТОЕ время | C23: =net_days*eff_hours -> 1533 | D23: ч/год | E23: net_days*eff_hours | F23: calc | G23: net_days, eff_hours | H23: Верхний уровень: всё доступное время
A24: net_weeks | B24: Чистое время, недель | C24: =net_days/days_week -> 43.8 | D24: нед | E24: net_days/days_week | F24: calc | G24: net_days, days_week
A25: promo_per_day | B25: Продвижение, часов в день | C25: 2 | D25: ч/дн | F25: default | H25: Form009
A26: promo_time | B26: Продвижение за год | C26: =promo_per_day*net_days -> 438 | D26: ч/год | E26: promo_per_day*net_days | F26: calc | G26: promo_per_day, net_days | H26: Form009
A27: acc_mode | B27: ПЕРЕКЛЮЧАТЕЛЬ · учёт и планирование | C27: Веду самостоятельно | F27: default | H27: Form011 · Block14
A28: acc_per_quarter | B28: Учёт: часов в квартал, если веду сам | C28: 3 | D28: ч/кв | F28: default | H28: Form011
A29: accounting_time | B29: Учёт и планирование, время | C29: =IF(acc_mode="Веду самостоятельно",acc_per_quarter*quarters,0) -> 12 | D29: ч/год | E29: IF(acc_mode="Веду самостоятельно",acc_per_quarter*quarters,0) | F29: calc | G29: acc_mode, acc_per_quarter, quarters | H29: Если наняли — время = 0
A30: side_time | B30: ОПЕРАЦИОННОЕ время | C30: =promo_time+accounting_time -> 450 | D30: ч/год | E30: promo_time+accounting_time | F30: calc | G30: promo_time, accounting_time | H30: Второстепенные операции. Клиенту не продаётся
A31: pool_gross | B31: Время на заказы до резерва | C31: =net_time-side_time -> 1083 | D31: ч/год | E31: net_time-side_time | F31: calc | G31: net_time, side_time | H31: Чистое минус операционное
A32: fm_on | B32: ПЕРЕКЛЮЧАТЕЛЬ · резерв времени на простой и форс-мажоры | C32: Не закладывать | F32: default | H32: Block14a | I32: Галочка «Учитывать резерв времени на простой и форс-мажоры» СНЯТА по умолчанию (06.08.2026). Поле % неактивно, пока не включена
A33: fm_pct | B33: Резерв времени на простой и форс-мажоры, % | C33: 0.05 | D33: % | F33: default | H33: Периоды без заказов, перенос и отмена съёмок, срывы по вине клиента, повторные выезды. Редактируется | I33: Галочка «Учитывать резерв времени на простой и форс-мажоры» СНЯТА по умолчанию (06.08.2026). Поле % неактивно, пока не включена
A34: fm_time | B34: Резерв времени на простой и форс-мажоры, часов | C34: =IF(fm_on="Заложить резерв",pool_gross*fm_pct,0) -> 0 | D34: ч/год | E34: IF(fm_on="Заложить резерв",pool_gross*fm_pct,0) | F34: calc | G34: fm_on, fm_pct, pool_gross | H34: Вычитается из времени на заказы
A35: fm_week | B35: Резерв, часов в неделю | C35: =IF(net_weeks=0,0,fm_time/net_weeks) -> 0 | D35: ч/нед | E35: IF(net_weeks=0,0,fm_time/net_weeks) | F35: calc | G35: fm_time, net_weeks | H35: Для наглядности
A36: project_pool | B36: ПРОЕКТНОЕ время за год | C36: =pool_gross-fm_time -> 1083 | D36: ч/год | E36: pool_gross-fm_time | F36: calc | G36: pool_gross, fm_time | H36: Всё, что остаётся на выполнение проектов
A37: 3 · ПРОЕКТ — S × (1+K) + 1. Длительность съёмки задаёт пользователь
A38: ID | B38: Название | C38: Значение | D38: Ед. | E38: Формула / как получено | F38: Тип | G38: Зависит от | H38: Источник / форма
A39: post_ratio | B39: Коэффициент обработки | C39: 3 | D39: × | F39: default | H39: Часов обработки на 1 час съёмки. МЕНЯЕТСЯ пользователем: у свадебного ретушёра больше, у репортажника меньше
A40: profile_multiplier | B40: Множитель профильного времени | C40: =1+post_ratio -> 4 | D40: × | E40: 1+post_ratio | F40: calc | G40: post_ratio | H40: ПРОФИЛЬНОЕ на проект = S × (1 + коэффициент): съёмка плюс обработка
A41: client_time | B41: Работа с клиентом на проект | C41: 1 | D41: ч/проект | F41: default | H41: Form012 · Block13 · продажа, согласования, организация
...

Sheet Состав
A1: СОСТАВ · ЧТО ИЗ ЧЕГО СКЛАДЫВАЕТСЯ
A2: Лист содержит только группирующие понятия и фиксирует, какие понятия и поля калькулятора входят в их состав. Формулы, алгоритмы вычисления, пользовательские вводы и отдельные расчётные показатели сюда не заносятся: формулы хранятся на листе calc, подробные алгоритмы — в паспортах расчётов. Наименования берутся только из листа 01_Глоссарий; ID — из calc.html.
C3: Составные части
A4: ID | B4: Наименование | C4: 1 | D4: 2 | E4: 3 | F4: 4 | G4: 5 | H4: 6 | I4: 7 | J4: 8 | K4: 9 | L4: 10
A5: R | B5: Выручка | C5: Желаемый доход | D5: Финансовые расходы | E5: Налоги | F5: Эквайринг | G5: Инвестиционное время | H5: Резерв на развитие | I5: Резерв на программу лояльности
A6: C | B6: Финансовые расходы | C6: Финансовые вложения (инвестиции) | D6: Регулярные расходы специалиста
A7: — | B7: Всего расходов | C7: Финансовые расходы | D7: Налоги | E7: Эквайринг
A8: — | B8: Резервный фонд | C8: Резерв на отпуск | D8: Резерв на развитие | E8: Резерв на программу лояльности
A9: vari | B9: Регулярные расходы специалиста | C9: Подписки | D9: Реклама | E9: Банковское обслуживание | F9: Бухгалтерия | G9: Содержание рабочего места
A10: amort | B10: Финансовые вложения (инвестиции) | C10: Съёмочное оборудование | D10: Офисное оборудование | E10: ПО | F10: Обустройство рабочего места | G10: Обучение | H10: Сайт
A11: workHours | B11: Временные расходы | C11: Съёмочное время | D11: Время на постпродакшн | E11: Проектное клиентское время | F11: Поиск заказов | G11: Учёт | H11: Резерв времени на простой и форс-мажоры | I11: Неэффективное рабочее время
A12: — | B12: Инвестиционное время | C12: Обучение | D12: Сайт

Sheet 03_Каталоги
A1: 03 · КАТАЛОГИ — списки значений по умолчанию для форм калькулятора
A2: Только данные, никаких строк «ИТОГО». Итог берётся формулой SUMIF по коду формы. Период: Год=1, Месяц=12, Квартал=4 — как в ваших выпадающих списках.
A4: Форма | B4: Позиция | C4: Стоимость, ₽ | D4: Срок, лет | E4: Период | F4: Платежей/год | G4: ₽/год | H4: Тип расхода
A5: Form001 | B5: Canon EOS R6 Mark II Body | C5: 166999 | D5: 3 | F5: =IF(E5="Год",1,IF(E5="Квартал",4,IF(E5="Месяц",12,0))) -> 0 | G5: =IF(N(D5)>0,C5/D5,C5*F5) -> 55666.333 | H5: амортизация
A6: Form001 | B6: Canon RF 24–105mm f/4.0 L IS USM | C6: 130999 | D6: 5 | F6: =IF(E6="Год",1,IF(E6="Квартал",4,IF(E6="Месяц",12,0))) -> 0 | G6: =IF(N(D6)>0,C6/D6,C6*F6) -> 26199.8 | H6: амортизация
A7: Form001 | B7: Godox V1Pro C | C7: 36990 | D7: 5 | F7: =IF(E7="Год",1,IF(E7="Квартал",4,IF(E7="Месяц",12,0))) -> 0 | G7: =IF(N(D7)>0,C7/D7,C7*F7) -> 7398 | H7: амортизация
A8: Form001 | B8: Godox XPro II C | C8: 9355 | D8: 5 | F8: =IF(E8="Год",1,IF(E8="Квартал",4,IF(E8="Месяц",12,0))) -> 0 | G8: =IF(N(D8)>0,C8/D8,C8*F8) -> 1871 | H8: амортизация
A9: Form001 | B9: Аккумулятор LP-E6NH | C9: 12978 | D9: 3 | F9: =IF(E9="Год",1,IF(E9="Квартал",4,IF(E9="Месяц",12,0))) -> 0 | G9: =IF(N(D9)>0,C9/D9,C9*F9) -> 4326 | H9: амортизация
A10: Form001 | B10: SanDisk Extreme PRO 256 ГБ #1 | C10: 6990 | D10: 2 | F10: =IF(E10="Год",1,IF(E10="Квартал",4,IF(E10="Месяц",12,0))) -> 0 | G10: =IF(N(D10)>0,C10/D10,C10*F10) -> 3495 | H10: амортизация
A11: Form001 | B11: SanDisk Extreme PRO 256 ГБ #2 | C11: 6990 | D11: 2 | F11: =IF(E11="Год",1,IF(E11="Квартал",4,IF(E11="Месяц",12,0))) -> 0 | G11: =IF(N(D11)>0,C11/D11,C11*F11) -> 3495 | H11: амортизация
A12: Form001 | B12: Рюкзак Lowepro ProTactic | C12: 27962 | D12: 7 | F12: =IF(E12="Год",1,IF(E12="Квартал",4,IF(E12="Месяц",12,0))) -> 0 | G12: =IF(N(D12)>0,C12/D12,C12*F12) -> 3994.5714 | H12: амортизация
A13: Form001 | B13: Godox RFT-05 отражатель | C13: 3000 | D13: 5 | F13: =IF(E13="Год",1,IF(E13="Квартал",4,IF(E13="Месяц",12,0))) -> 0 | G13: =IF(N(D13)>0,C13/D13,C13*F13) -> 600 | H13: амортизация
A14: Form001 | B14: X-Rite ColorChecker | C14: 5000 | D14: 7 | F14: =IF(E14="Год",1,IF(E14="Квартал",4,IF(E14="Месяц",12,0))) -> 0 | G14: =IF(N(D14)>0,C14/D14,C14*F14) -> 714.28571 | H14: амортизация
A15: Form002 | B15: Системный блок | C15: 180000 | D15: 5 | F15: =IF(E15="Год",1,IF(E15="Квартал",4,IF(E15="Месяц",12,0))) -> 0 | G15: =IF(N(D15)>0,C15/D15,C15*F15) -> 36000 | H15: амортизация
A16: Form002 | B16: Монитор ASUS ProArt | C16: 55000 | D16: 5 | F16: =IF(E16="Год",1,IF(E16="Квартал",4,IF(E16="Месяц",12,0))) -> 0 | G16: =IF(N(D16)>0,C16/D16,C16*F16) -> 11000 | H16: амортизация
... A30: Form013 | B30: Косметический ремонт | C30: 30000 | D30: 7 | F30: =IF(E30="Год",1,IF(E30="Квартал",4,IF(E30="Месяц",12,0))) -> 0 | G30: =IF(N(D30)>0,C30/D30,C30*F30) -> 4285.7143 | H30: амортизация
A31: Form003 | B31: Adobe CC Photography | C31: 2000 | E31: Месяц | F31: =IF(E31="Год",1,IF(E31="Квартал",4,IF(E31="Месяц",12,0))) -> 12 | G31: =IF(N(D31)>0,C31/D31,C31*F31) -> 24000 | H31: регулярный платёж
A32: Form003 | B32: Яндекс Диск 1 ТБ | C32: 250 | E32: Месяц | F32: =IF(E32="Год",1,IF(E32="Квартал",4,IF(E32="Месяц",12,0))) -> 12 | G32: =IF(N(D32)>0,C32/D32,C32*F32) -> 3000 | H32: регулярный платёж
A33: Form007 | B33: Обслуживание счёта (РКО) | C33: 0 | E33: Месяц | F33: =IF(E33="Год",1,IF(E33="Квартал",4,IF(E33="Месяц",12,0))) -> 12 | G33: =IF(N(D33)>0,C33/D33,C33*F33) -> 0 | H33: регулярный платёж
A34: Form007 | B34: СМС-уведомления | C34: 150 | E34: Месяц | F34: =IF(E34="Год",1,IF(E34="Квартал",4,IF(E34="Месяц",12,0))) -> 12 | G34: =IF(N(D34)>0,C34/D34,C34*F34) -> 1800 | H34: регулярный платёж
A35: Form010 | B35: Домен сайта | C35: 1500 | E35: Год | F35: =IF(E35="Год",1,IF(E35="Квартал",4,IF(E35="Месяц",12,0))) -> 1 | G35: =IF(N(D35)>0,C35/D35,C35*F35) -> 1500 | H35: регулярный платёж
A36: Form010 | B36: Хостинг сайта | C36: 6000 | E36: Год | F36: =IF(E36="Год",1,IF(E36="Квартал",4,IF(E36="Месяц",12,0))) -> 1 | G36: =IF(N(D36)>0,C36/D36,C36*F36) -> 6000 | H36: регулярный платёж
A37: Form010 | B37: Яндекс Директ | C37: 15000 | E37: Месяц | F37: =IF(E37="Год",1,IF(E37="Квартал",4,IF(E37="Месяц",12,0))) -> 12 | G37: =IF(N(D37)>0,C37/D37,C37*F37) -> 180000 | H37: регулярный платёж
A38: Form010 | B38: Авито | C38: 0 | E38: Месяц | F38: =IF(E38="Год",1,IF(E38="Квартал",4,IF(E38="Месяц",12,0))) -> 12 | G38: =IF(N(D38)>0,C38/D38,C38*F38) -> 0 | H38: регулярный платёж
A39: Form010 | B39: Таргетированная реклама | C39: 0 | E39: Месяц | F39: =IF(E39="Год",1,IF(E39="Квартал",4,IF(E39="Месяц",12,0))) -> 12 | G39: =IF(N(D39)>0,C39/D39,C39*F39) -> 0 | H39: регулярный платёж
A40: Form010 | B40: Платные размещения у блогеров | C40: 0 | E40: Месяц | F40: =IF(E40="Год",1,IF(E40="Квартал",4,IF(E40="Месяц",12,0))) -> 12 | G40: =IF(N(D40)>0,C40/D40,C40*F40) -> 0 | H40: регулярный платёж
A41: Form010 | B41: Отклики на Profi.ru | C41: 0 | E41: Месяц | F41: =IF(E41="Год",1,IF(E41="Квартал",4,IF(E41="Месяц",12,0))) -> 12 | G41: =IF(N(D41)>0,C41/D41,C41*F41) -> 0 | H41: регулярный платёж

Sheet 04_Итог
A1: 04 · ИТОГ по выбранному режиму
A3: ГЛАВНЫЙ РЕЗУЛЬТАТ
A4: Выбранный режим | B4: =regime -> Самозанятый (НПД), средняя ставка | C4: меняется в calc → regime
A5: Ставка часа съёмки, ₽/час | B5: =CHOOSE(regime_no,'05_Расчёт'!B19,'05_Расчёт'!C19,'05_Расчёт'!D19,'05_Расчёт'!E19,'05_Расчёт'!F19,'05_Расчёт'!G19,'05_Расчёт'!H19) -> 9429.986 | C5: цена съёмочного часа для клиента
A6: Стоимость проекта, ₽ | B6: =CHOOSE(regime_no,'05_Расчёт'!B20,'05_Расчёт'!C20,'05_Расчёт'!D20,'05_Расчёт'!E20,'05_Расчёт'!F20,'05_Расчёт'!G20,'05_Расчёт'!H20) -> 9429.986
A7: Базовая ставка, ₽/час | B7: =base_rate -> 1332.3777 | C7: цена любого часа: съёмка, обработка, продвижение
A8: Выручка, ₽/год | B8: =CHOOSE(regime_no,'05_Расчёт'!B4,'05_Расчёт'!C4,'05_Расчёт'!D4,'05_Расчёт'!E4,'05_Расчёт'!F4,'05_Расчёт'!G4,'05_Расчёт'!H4) -> 2042535
A9: Выручка, ₽/месяц | B9: =CHOOSE(regime_no,'05_Расчёт'!B5,'05_Расчёт'!C5,'05_Расчёт'!D5,'05_Расчёт'!E5,'05_Расчёт'!F5,'05_Расчёт'!G5,'05_Расчёт'!H5) -> 170211.25
A10: Всего налогов и взносов, ₽/год | B10: =CHOOSE(regime_no,'05_Расчёт'!B15,'05_Расчёт'!C15,'05_Расчёт'!D15,'05_Расчёт'!E15,'05_Расчёт'!F15,'05_Расчёт'!G15,'05_Расчёт'!H15) -> 102126.75
A11: Эффективная нагрузка | B11: =CHOOSE(regime_no,'05_Расчёт'!B17,'05_Расчёт'!C17,'05_Расчёт'!D17,'05_Расчёт'!E17,'05_Расчёт'!F17,'05_Расчёт'!G17,'05_Расчёт'!H17) -> 0.05
A12: Точка безубыточности, ₽/год | B12: =CHOOSE(regime_no,'05_Расчёт'!B22,'05_Расчёт'!C22,'05_Расчёт'!D22,'05_Расчёт'!E22,'05_Расчёт'!F22,'05_Расчёт'!G22,'05_Расчёт'!H22) -> 609607.56
A13: ВРЕМЯ — иерархия
A14: ЧИСТОЕ время (всё доступное) | B14: =net_time -> 1533 | C14: производств. календарь − отпуск − больничный − час/день
A15: ├ ОПЕРАЦИОННОЕ (второстепенное) | B15: =side_time -> 450 | C15: продвижение + учёт
A16: ├ РЕЗЕРВ ВРЕМЕНИ на простой и форс-мажоры | B16: =fm_time -> 0 | C16: периоды без заказов, переносы, отмены, срывы
A17: └ ПРОЕКТНОЕ за год | B17: =project_pool -> 1083 | C17: на выполнение всех проектов
A18: ├ ПРОФИЛЬНОЕ (по профилю) | B18: =core_time -> 866.4 | C18: S × (1+коэф.): площадка + обработка
A19: │ ├ СЪЁМОЧНОЕ ← ЦЕЛЬ | B19: =shooting_time -> 216.6 | C19: S — работа на площадке
A20: │ └ постпродакшн | B20: =post_time -> 649.8 | C20: S × коэффициент — обработка
A21: └ работа с клиентом | B21: =client_total -> 216.6 | C21: 1 ч на проект: продажа, согласования
A22: Продолжительность съёмки (S) | B22: =shoot_duration -> 1 | C22: типовой заказ, задаёт пользователь
A23: Коэффициент обработки | B23: =post_ratio -> 3 | C23: часов обработки на 1 час съёмки
A24: Проектное время на 1 проект | B24: =project_time -> 5 | C24: S × (1+коэф.) + 1
A25: Проектов в год | B25: =projects_year -> 216.6
A26: Проектов в неделю | B26: =projects_week -> 4.9452055 | C26: при авторежиме = 1
A28: ПРОВЕРКА ИЕРАРХИИ ВРЕМЕНИ
A29: Операционное + резерв + проектное = чистое | B29: =IF(ABS(side_time+fm_time+project_pool-net_time)<0.01,"OK","ОШИБКА") -> OK
A30: Профильное + клиентское = проектное | B30: =IF(ABS(core_time+client_total-project_pool)<0.01,"OK","ОШИБКА") -> OK
A31: Съёмочное + постпродакшн = профильное | B31: =IF(ABS(shooting_time+post_time-core_time)<0.01,"OK","ОШИБКА") -> OK
A33: РАСХОДЫ
A34: Амортизация | B34: =investment -> 278687.78
A35: Переменные расходы | B35: =variable_costs -> 283980
A36: ВСЕГО расходов (C) | B36: =total_costs -> 562667.78
A37: Эквайринг (% от выручки) | B37: =acquiring -> 0.027
A38: Ваша текущая ставка, ₽/час | B38: =current_rate -> 6000
A39: СКОЛЬКО ВЫ ТЕРЯЕТЕ
A41: Остаётся на руки за год при текущей ставке, ₽ | B41: =(current_rate*shooting_time)*(1-rate_current-acquiring)-total_costs -> 636863.02
A42: Ваша расчётная ставка, ₽/час | B42: =B5 -> 9429.986
A43: Разница с текущей, ₽/час | B43: =B5-current_rate -> 3429.986
A44: Недополучено за год, ₽ | B44: =target_income-B41 -> 685728.98
...

Sheet 05_Расчёт
A1: 05 · РАСЧЁТ — семь режимов, как в вашем выпадающем списке
A3: Показатель | B3: НПД средняя 5% | C3: НПД физлица 4% | D3: НПД юрлица 6% | E3: УСН Доходы 6% | F3: УСН Д−Р 15% | G3: АУСН Доходы 8% | H3: АУСН Д−Р 20%
A4: ВЫРУЧКА, ₽/год | B4: =(target_income+total_costs)/((1-acquiring-site_divisor)-rate_npd_avg) -> 2042535 | C4: =(target_income+total_costs)/((1-acquiring-site_divisor)-rate_npd_fiz) -> 2020642.9 | D4: =(target_income+total_costs)/((1-acquiring-site_divisor)-rate_npd_ur) -> 2064906.7 | E4: =MAX(((target_income+total_costs)+fixed_contrib-threshold_credit)/((1-acquiring-site_divisor)-extra_contrib),(target_income+total_costs)/((1-acquiring-site_divisor)-rate_usn_inc)) -> 2064906.7 | F4: =((target_income/(1-rate_usn_prof))+(fixed_contrib-threshold_credit+extra_contrib*(target_income/(1-rate_usn_prof)))+total_costs)/(1-acquiring-site_divisor) -> 2249340.5 | G4: =((target_income+total_costs)+injury_contrib)/((1-acquiring-site_divisor)-rate_ausn_inc) -> 2111153.2 | H4: =((target_income/(1-rate_ausn_prof))+total_costs+injury_contrib)/(1-acquiring-site_divisor) -> 2277397.5
A5: Выручка, ₽/месяц | B5: =B4/months -> 170211.25 | C5: =C4/months -> 168386.9 | D5: =D4/months -> 172075.56 | E5: =E4/months -> 172075.56 | F5: =F4/months -> 187445.04 | G5: =G4/months -> 175929.43 | H5: =H4/months -> 189783.13
A7: Эквайринг, ₽/год | B7: =B4*acquiring -> 55148.444 | C7: =C4*acquiring -> 54557.357 | D7: =D4*acquiring -> 55752.48 | E7: =E4*acquiring -> 55752.48 | F7: =F4*acquiring -> 60732.193 | G7: =G4*acquiring -> 57001.136 | H7: =H4*acquiring -> 61489.733
A8: Страховые взносы (фикс.) | B8: =0 -> 0 | C8: =0 -> 0 | D8: =0 -> 0 | E8: =fixed_contrib -> 57390 | F8: =fixed_contrib -> 57390 | G8: =0 -> 0 | H8: =0 -> 0
A9: База для доначисления 1% | B9: =0 -> 0 | C9: =0 -> 0 | D9: =0 -> 0 | E9: =MAX(0,E4-contrib_threshold) -> 1764906.7 | F9: =MAX(0,(target_income/(1-rate_usn_prof))-contrib_threshold) -> 1255990.6 | G9: =0 -> 0 | H9: =0 -> 0
A10: Доначисление 1% | B10: =0 -> 0 | C10: =0 -> 0 | D10: =0 -> 0 | E10: =MIN(E9*extra_contrib,contrib_cap) -> 17649.067 | F10: =MIN(F9*extra_contrib,contrib_cap) -> 12559.906 | G10: =0 -> 0 | H10: =0 -> 0
A11: Налог | B11: =B4*rate_npd_avg -> 102126.75 | C11: =C4*rate_npd_fiz -> 80825.714 | D11: =D4*rate_npd_ur -> 123894.4 | E11: =MAX(0,E4*rate_usn_inc-(E8+E10)) -> 48855.333 | F11: =MAX((target_income/(1-rate_usn_prof))*rate_usn_prof,F4*min_tax_usn) -> 233398.59 | G11: =G4*rate_ausn_inc -> 168892.25 | H11: =MAX((target_income/(1-rate_ausn_prof))*rate_ausn_prof,H4*min_tax_ausn) -> 330648
A12: Взнос на травматизм | B12: =0 -> 0 | C12: =0 -> 0 | D12: =0 -> 0 | E12: =0 -> 0 | F12: =0 -> 0 | G12: =injury_contrib -> 0 | H12: =injury_contrib -> 0
A13: Применён минимальный налог? | B13: ="—" -> — | C13: ="—" -> — | D13: ="—" -> — | E13: ="—" -> — | F13: =IF((target_income/(1-rate_usn_prof))*rate_usn_prof<F4*min_tax_usn,"ДА","нет") -> нет | G13: ="—" -> — | H13: =IF((target_income/(1-rate_ausn_prof))*rate_ausn_prof<H4*min_tax_ausn,"ДА","нет") -> нет
A15: ВСЕГО налогов и взносов | B15: =B8+B10+B11+B12 -> 102126.75 | C15: =C8+C10+C11+C12 -> 80825.714 | D15: =D8+D10+D11+D12 -> 123894.4 | E15: =E8+E10+E11+E12 -> 123894.4 | F15: =F8+F10+F11+F12 -> 303348.49 | G15: =G8+G10+G11+G12 -> 168892.25 | H15: =H8+H10+H11+H12 -> 330648
A16: Всего налогов и взносов, ₽/мес | B16: =B15/months -> 8510.5624 | C16: =C15/months -> 6735.4762 | D16: =D15/months -> 10324.533 | E16: =E15/months -> 10324.533 | F16: =F15/months -> 25279.041 | G16: =G15/months -> 14074.354 | H16: =H15/months -> 27554
A17: Эффективная нагрузка | B17: =IF(B4=0,0,B15/B4) -> 0.05 | C17: =IF(C4=0,0,C15/C4) -> 0.04 | D17: =IF(D4=0,0,D15/D4) -> 0.06 | E17: =IF(E4=0,0,E15/E4) -> 0.06 | F17: =IF(F4=0,0,F15/F4) -> 0.13486108 | G17: =IF(G4=0,0,G15/G4) -> 0.08 | H17: =IF(H4=0,0,H15/H4) -> 0.14518677
A19: ПОЛНАЯ СТАВКА ЧАСА, ₽/час | B19: =IF(shooting_time=0,0,B4/shooting_time) -> 9429.986 | C19: =IF(shooting_time=0,0,C4/shooting_time) -> 9328.9144 | D19: =IF(shooting_time=0,0,D4/shooting_time) -> 9533.2717 | E19: =IF(shooting_time=0,0,E4/shooting_time) -> 9533.2717 | F19: =IF(shooting_time=0,0,F4/shooting_time) -> 10384.767 | G19: =IF(shooting_time=0,0,G4/shooting_time) -> 9746.7829 | H19: =IF(shooting_time=0,0,H4/shooting_time) -> 10514.301
A20: Стоимость проекта, ₽ | B20: =IF(projects_year=0,0,B4/projects_year) -> 9429.986 | C20: =IF(projects_year=0,0,C4/projects_year) -> 9328.9144 | D20: =IF(projects_year=0,0,D4/projects_year) -> 9533.2717 | E20: =IF(projects_year=0,0,E4/projects_year) -> 9533.2717 | F20: =IF(projects_year=0,0,F4/projects_year) -> 10384.767 | G20: =IF(projects_year=0,0,G4/projects_year) -> 9746.7829 | H20: =IF(projects_year=0,0,H4/projects_year) -> 10514.301
A22: Точка безубыточности, ₽/год | B22: =total_costs/((1-acquiring-site_divisor)-rate_npd_avg) -> 609607.56 | C22: =total_costs/((1-acquiring-site_divisor)-rate_npd_fiz) -> 603073.72 | D22: =total_costs/((1-acquiring-site_divisor)-rate_npd_ur) -> 616284.54 | E22: =MAX((total_costs+fixed_contrib-threshold_credit)/((1-acquiring-site_divisor)-extra_contrib),total_costs/((1-acquiring-site_divisor)-rate_usn_inc)) -> 640766.13 | F22: =(total_costs+fixed_contrib)/((1-acquiring-site_divisor)-min_tax_usn) -> 643881.39 | G22: =(total_costs+injury_contrib)/((1-acquiring-site_divisor)-rate_ausn_inc) -> 630087.1 | H22: =(total_costs+injury_contrib)/((1-acquiring-site_divisor)-min_tax_ausn) -> 596678.45
A23: ПРОВЕРКА безубыточности (=0) | B23: =B22-total_costs-B22*acquiring-B22*rate_npd_avg -> 1.8189894e-11 | C23: =C22-total_costs-C22*acquiring-C22*rate_npd_fiz -> 7.2759576e-11 | D23: =D22-total_costs-D22*acquiring-D22*rate_npd_ur -> -5.0931703e-11 | E23: =E22-total_costs-E22*acquiring-MAX(fixed_contrib+MIN(MAX(0,E22-contrib_threshold)*extra_contrib,contrib_cap),E22*rate_usn_inc) -> -3.6379788e-11 | F23: =F22-total_costs-F22*acquiring-fixed_contrib-F22*min_tax_usn -> -3.5470293e-11 | G23: =G22-total_costs-G22*acquiring-G22*rate_ausn_inc -> -2.1827873e-11 | H23: =H22-total_costs-H22*acquiring-H22*min_tax_ausn -> 7.2759576e-12
A24: ПРОВЕРКА: остаётся на руки | B24: =B4-total_costs-B7-B15 -> 1322592 | C24: =C4-total_costs-C7-C15 -> 1322592 | D24: =D4-total_costs-D7-D15 -> 1322592 | E24: =E4-total_costs-E7-E15 -> 1322592 | F24: =F4-total_costs-F7-F15 -> 1322592 | G24: =G4-total_costs-G7-G15 -> 1322592 | H24: =H4-total_costs-H7-H15 -> 1322592
A25: Контроль лимитов | B25: =IF(B4>limit_npd,"! лимит НПД","ок") -> ок | C25: =IF(C4>limit_npd,"! лимит НПД","ок") -> ок | D25: =IF(D4>limit_npd,"! лимит НПД","ок") -> ок | E25: =IF(E4>vat_threshold,"! НДС","ок") -> ок | F25: =IF(F4>vat_threshold,"! НДС","ок") -> ок | G25: =IF(G4>limit_ausn,"! лимит АУСН","ок") -> ок | H25: =IF(H4>limit_ausn,"! лимит АУСН","ок") -> ок

Sheet 06_Отчёт
A1: 06 · ОТЧЁТ — куда уходит каждый рубль с часа съёмки
A2: Личный доход разложен по ролям: фотограф, ретушёр, менеджер, маркетолог, бухгалтер. Расходы — по назначению.
A4: 1 · ВАШ ЛИЧНЫЙ ДОХОД ПО РОЛЯМ (ставка любого рабочего часа = доход / чистое время)
A5: Статья | B5: ₽/год | C5: ₽/месяц | D5: ₽/съём. час | E5: ₽/проект | F5: доля | G5: часов/год
A6: Как ФОТОГРАФ — работа на площадке | B6: =(target_income/net_time)*shooting_time -> 186871.12 | C6: =IF(months=0,0,B6/months) -> 15572.593 | D6: =IF(shooting_time=0,0,B6/shooting_time) -> 862.74755 | E6: =IF(projects_year=0,0,B6/projects_year) -> 862.74755 | F6: =IF((CHOOSE(regime_no,'05_Расчёт'!B4,'05_Расчёт'!C4,'05_Расчёт'!D4,'05_Расчёт'!E4,'05_Расчёт'!F4,'05_Расчёт'!G4,'05_Расчёт'!H4))=0,0,B6/(CHOOSE(regime_no,'05_Расчёт'!B4,'05_Расчёт'!C4,'05_Расчёт'!D4,'05_Расчёт'!E4,'05_Расчёт'!F4,'05_Расчёт'!G4,'05_Расчёт'!H4))) -> 0.091489802 | G6: =shooting_time -> 216.6
A7: Как РЕТУШЁР — обработка материала | B7: =(target_income/net_time)*post_time -> 560613.36 | C7: =IF(months=0,0,B7/months) -> 46717.78 | D7: =IF(shooting_time=0,0,B7/shooting_time) -> 2588.2427 | E7: =IF(projects_year=0,0,B7/projects_year) -> 2588.2427 | F7: =IF((CHOOSE(regime_no,'05_Расчёт'!B4,'05_Расчёт'!C4,'05_Расчёт'!D4,'05_Расчёт'!E4,'05_Расчёт'!F4,'05_Расчёт'!G4,'05_Расчёт'!H4))=0,0,B7/(CHOOSE(regime_no,'05_Расчёт'!B4,'05_Расчёт'!C4,'05_Расчёт'!D4,'05_Расчёт'!E4,'05_Расчёт'!F4,'05_Расчёт'!G4,'05_Расчёт'!H4))) -> 0.27446941 | G7: =post_time -> 649.8
A8: Как МЕНЕДЖЕР — работа с клиентом | B8: =(target_income/net_time)*client_total -> 186871.12 | C8: =IF(months=0,0,B8/months) -> 15572.593 | D8: =IF(shooting_time=0,0,B8/shooting_time) -> 862.74755 | E8: =IF(projects_year=0,0,B8/projects_year) -> 862.74755 | F8: =IF((CHOOSE(regime_no,'05_Расчёт'!B4,'05_Расчёт'!C4,'05_Расчёт'!D4,'05_Расчёт'!E4,'05_Расчёт'!F4,'05_Расчёт'!G4,'05_Расчёт'!H4))=0,0,B8/(CHOOSE(regime_no,'05_Расчёт'!B4,'05_Расчёт'!C4,'05_Расчёт'!D4,'05_Расчёт'!E4,'05_Расчёт'!F4,'05_Расчёт'!G4,'05_Расчёт'!H4))) -> 0.091489802 | G8: =client_total -> 216.6
A9: Как МАРКЕТОЛОГ — продвижение | B9: =(target_income/net_time)*promo_time -> 377883.43 | C9: =IF(months=0,0,B9/months) -> 31490.286 | D9: =IF(shooting_time=0,0,B9/shooting_time) -> 1744.6142 | E9: =IF(projects_year=0,0,B9/projects_year) -> 1744.6142 | F9: =IF((CHOOSE(regime_no,'05_Расчёт'!B4,'05_Расчёт'!C4,'05_Расчёт'!D4,'05_Расчёт'!E4,'05_Расчёт'!F4,'05_Расчёт'!G4,'05_Расчёт'!H4))=0,0,B9/(CHOOSE(regime_no,'05_Расчёт'!B4,'05_Расчёт'!C4,'05_Расчёт'!D4,'05_Расчёт'!E4,'05_Расчёт'!F4,'05_Расчёт'!G4,'05_Расчёт'!H4))) -> 0.18500708 | G9: =promo_time -> 438
A10: Как БУХГАЛТЕР — учёт и отчётность | B10: =(target_income/net_time)*accounting_time -> 10352.971 | C10: =IF(months=0,0,B10/months) -> 862.74755 | D10: =IF(shooting_time=0,0,B10/shooting_time) -> 47.797648 | E10: =IF(projects_year=0,0,B10/projects_year) -> 47.797648 | F10: =IF((CHOOSE(regime_no,'05_Расчёт'!B4,'05_Расчёт'!C4,'05_Расчёт'!D4,'05_Расчёт'!E4,'05_Расчёт'!F4,'05_Расчёт'!G4,'05_Расчёт'!H4))=0,0,B10/(CHOOSE(regime_no,'05_Расчёт'!B4,'05_Расчёт'!C4,'05_Расчёт'!D4,'05_Расчёт'!E4,'05_Расчёт'!F4,'05_Расчёт'!G4,'05_Расчёт'!H4))) -> 0.0050686871 | G10: =accounting_time -> 12
A11: Компенсация простоя и форс-мажоров | B11: =(target_income/net_time)*fm_time -> 0 | C11: =IF(months=0,0,B11/months) -> 0 | D11: =IF(shooting_time=0,0,B11/shooting_time) -> 0 | E11: =IF(projects_year=0,0,B11/projects_year) -> 0 | F11: =IF((CHOOSE(regime_no,'05_Расчёт'!B4,'05_Расчёт'!C4,'05_Расчёт'!D4,'05_Расчёт'!E4,'05_Расчёт'!F4,'05_Расчёт'!G4,'05_Расчёт'!H4))=0,0,B11/(CHOOSE(regime_no,'05_Расчёт'!B4,'05_Расчёт'!C4,'05_Расчёт'!D4,'05_Расчёт'!E4,'05_Расчёт'!F4,'05_Расчёт'!G4,'05_Расчёт'!H4))) -> 0 | G11: =fm_time -> 0
A12: ИТОГО НА РУКИ | B12: =target_income -> 1322592 | C12: =IF(months=0,0,B12/months) -> 110216 | D12: =IF(shooting_time=0,0,B12/shooting_time) -> 6106.1496 | E12: =IF(projects_year=0,0,B12/projects_year) -> 6106.1496 | F12: =IF((CHOOSE(regime_no,'05_Расчёт'!B4,'05_Расчёт'!C4,'05_Расчёт'!D4,'05_Расчёт'!E4,'05_Расчёт'!F4,'05_Расчёт'!G4,'05_Расчёт'!H4))=0,0,B12/(CHOOSE(regime_no,'05_Расчёт'!B4,'05_Расчёт'!C4,'05_Расчёт'!D4,'05_Расчёт'!E4,'05_Расчёт'!F4,'05_Расчёт'!G4,'05_Расчёт'!H4))) -> 0.64752478 | G12: =net_time -> 1533
A14: 2 · ОТЛОЖИТЬ НА ВОССТАНОВЛЕНИЕ ВЛОЖЕНИЙ (амортизация)
A15: Статья | B15: ₽/год | C15: ₽/месяц | D15: ₽/съём. час | E15: ₽/проект | F15: доля | G15: часов/год
A16: На съёмочное оборудование | B16: =dep_shoot -> 107759.99 | C16: =IF(months=0,0,B16/months) -> 8979.9992 | D16: =IF(shooting_time=0,0,B16/shooting_time) -> 497.50688 | E16: =IF(projects_year=0,0,B16/projects_year) -> 497.50688 | F16: =IF((CHOOSE(regime_no,'05_Расчёт'!B4,'05_Расчёт'!C4,'05_Расчёт'!D4,'05_Расчёт'!E4,'05_Расчёт'!F4,'05_Расчёт'!G4,'05_Расчёт'!H4))=0,0,B16/(CHOOSE(regime_no,'05_Расчёт'!B4,'05_Расчёт'!C4,'05_Расчёт'!D4,'05_Расчёт'!E4,'05_Расчёт'!F4,'05_Расчёт'!G4,'05_Расчёт'!H4))) -> 0.052757966
A17: На офисное оборудование | B17: =dep_office -> 65732.933 | C17: =IF(months=0,0,B17/months) -> 5477.7444 | D17: =IF(shooting_time=0,0,B17/shooting_time) -> 303.47615 | E17: =IF(projects_year=0,0,B17/projects_year) -> 303.47615 | F17: =IF((CHOOSE(regime_no,'05_Расчёт'!B4,'05_Расчёт'!C4,'05_Расчёт'!D4,'05_Расчёт'!E4,'05_Расчёт'!F4,'05_Расчёт'!G4,'05_Расчёт'!H4))=0,0,B17/(CHOOSE(regime_no,'05_Расчёт'!B4,'05_Расчёт'!C4,'05_Расчёт'!D4,'05_Расчёт'!E4,'05_Расчёт'!F4,'05_Расчёт'!G4,'05_Расчёт'!H4))) -> 0.032182036
A18: На ПО (разовые покупки) | B18: =dep_software -> 11500 | C18: =IF(months=0,0,B18/months) -> 958.33333 | D18: =IF(shooting_time=0,0,B18/shooting_time) -> 53.093259 | E18: =IF(projects_year=0,0,B18/projects_year) -> 53.093259 | F18: =IF((CHOOSE(regime_no,'05_Расчёт'!B4,'05_Расчёт'!C4,'05_Расчёт'!D4,'05_Расчёт'!E4,'05_Расчёт'!F4,'05_Расчёт'!G4,'05_Расчёт'!H4))=0,0,B18/(CHOOSE(regime_no,'05_Расчёт'!B4,'05_Расчёт'!C4,'05_Расчёт'!D4,'05_Расчёт'!E4,'05_Расчёт'!F4,'05_Расчёт'!G4,'05_Расчёт'!H4))) -> 0.0056302585
A19: На обустройство рабочего места | B19: =dep_workspace -> 9285.7143 | C19: =IF(months=0,0,B19/months) -> 773.80952 | D19: =IF(shooting_time=0,0,B19/shooting_time) -> 42.870334 | E19: =IF(projects_year=0,0,B19/projects_year) -> 42.870334 | F19: =IF((CHOOSE(regime_no,'05_Расчёт'!B4,'05_Расчёт'!C4,'05_Расчёт'!D4,'05_Расчёт'!E4,'05_Расчёт'!F4,'05_Расчёт'!G4,'05_Расчёт'!H4))=0,0,B19/(CHOOSE(regime_no,'05_Расчёт'!B4,'05_Расчёт'!C4,'05_Расчёт'!D4,'05_Расчёт'!E4,'05_Расчёт'!F4,'05_Расчёт'!G4,'05_Расчёт'!H4))) -> 0.0045461715
A20: На обучение | B20: =dep_education -> 74409.143 | C20: =IF(months=0,0,B20/months) -> 6200.7619 | D20: =IF(shooting_time=0,0,B20/shooting_time) -> 343.53252 | E20: =IF(projects_year=0,0,B20/projects_year) -> 343.53252 | F20: =IF((CHOOSE(regime_no,'05_Расчёт'!B4,'05_Расчёт'!C4,'05_Расчёт'!D4,'05_Расчёт'!E4,'05_Расчёт'!F4,'05_Расчёт'!G4,'05_Расчёт'!H4))=0,0,B20/(CHOOSE(regime_no,'05_Расчёт'!B4,'05_Расчёт'!C4,'05_Расчёт'!D4,'05_Расчёт'!E4,'05_Расчёт'!F4,'05_Расчёт'!G4,'05_Расчёт'!H4))) -> 0.036429801
A21: На сайт | B21: =dep_website -> 10000 | C21: =IF(months=0,0,B21/months) -> 833.33333 | D21: =IF(shooting_time=0,0,B21/shooting_time) -> 46.168052 | E21: =IF(projects_year=0,0,B21/projects_year) -> 46.168052 | F21: =IF((CHOOSE(regime_no,'05_Расчёт'!B4,'05_Расчёт'!C4,'05_Расчёт'!D4,'05_Расчёт'!E4,'05_Расчёт'!F4,'05_Расчёт'!G4,'05_Расчёт'!H4))=0,0,B21/(CHOOSE(regime_no,'05_Расчёт'!B4,'05_Расчёт'!C4,'05_Расчёт'!D4,'05_Расчёт'!E4,'05_Расчёт'!F4,'05_Расчёт'!G4,'05_Расчёт'!H4))) -> 0.004895877
A22: ИТОГО амортизация | B22: =investment -> 278687.78 | C22: =IF(months=0,0,B22/months) -> 23223.982 | D22: =IF(shooting_time=0,0,B22/shooting_time) -> 1286.6472 | E22: =IF(projects_year=0,0,B22/projects_year) -> 1286.6472 | F22: =IF((CHOOSE(regime_no,'05_Расчёт'!B4,'05_Расчёт'!C4,'05_Расчёт'!D4,'05_Расчёт'!E4,'05_Расчёт'!F4,'05_Расчёт'!G4,'05_Расчёт'!H4))=0,0,B22/(CHOOSE(regime_no,'05_Расчёт'!B4,'05_Расчёт'!C4,'05_Расчёт'!D4,'05_Расчёт'!E4,'05_Расчёт'!F4,'05_Расчёт'!G4,'05_Расчёт'!H4))) -> 0.13644211
A24: 3 · РЕГУЛЯРНЫЕ РАСХОДЫ
A25: Статья | B25: ₽/год | C25: ₽/месяц | D25: ₽/съём. час | E25: ₽/проект | F25: доля | G25: часов/год
A26: Подписки на ПО | B26: =var_software -> 27000 | C26: =IF(months=0,0,B26/months) -> 2250 | D26: =IF(shooting_time=0,0,B26/shooting_time) -> 124.65374 | E26: =IF(projects_year=0,0,B26/projects_year) -> 124.65374 | F26: =IF((CHOOSE(regime_no,'05_Расчёт'!B4,'05_Расчёт'!C4,'05_Расчёт'!D4,'05_Расчёт'!E4,'05_Расчёт'!F4,'05_Расчёт'!G4,'05_Расчёт'!H4))=0,0,B26/(CHOOSE(regime_no,'05_Расчёт'!B4,'05_Расчёт'!C4,'05_Расчёт'!D4,'05_Расчёт'!E4,'05_Расчёт'!F4,'05_Расчёт'!G4,'05_Расчёт'!H4))) -> 0.013218868
A27: Реклама и продвижение | B27: =var_ads -> 187500 | C27: =IF(months=0,0,B27/months) -> 15625 | D27: =IF(shooting_time=0,0,B27/shooting_time) -> 865.65097 | E27: =IF(projects_year=0,0,B27/projects_year) -> 865.65097 | F27: =IF((CHOOSE(regime_no,'05_Расчёт'!B4,'05_Расчёт'!C4,'05_Расчёт'!D4,'05_Расчёт'!E4,'05_Расчёт'!F4,'05_Расчёт'!G4,'05_Расчёт'!H4))=0,0,B27/(CHOOSE(regime_no,'05_Расчёт'!B4,'05_Расчёт'!C4,'05_Расчёт'!D4,'05_Расчёт'!E4,'05_Расчёт'!F4,'05_Расчёт'!G4,'05_Расчёт'!H4))) -> 0.091797694
A28: Банк: РКО и СМС | B28: =var_bank -> 1800 | C28: =IF(months=0,0,B28/months) -> 150 | D28: =IF(shooting_time=0,0,B28/shooting_time) -> 8.3102493 | E28: =IF(projects_year=0,0,B28/projects_year) -> 8.3102493 | F28: =IF((CHOOSE(regime_no,'05_Расчёт'!B4,'05_Расчёт'!C4,'05_Расчёт'!D4,'05_Расчёт'!E4,'05_Расчёт'!F4,'05_Расчёт'!G4,'05_Расчёт'!H4))=0,0,B28/(CHOOSE(regime_no,'05_Расчёт'!B4,'05_Расчёт'!C4,'05_Расчёт'!D4,'05_Расчёт'!E4,'05_Расчёт'!F4,'05_Расчёт'!G4,'05_Расчёт'!H4))) -> 0.00088125786
A29: Бухгалтер (0 = веду самостоятельно) | B29: =var_accounting -> 0 | C29: =IF(months=0,0,B29/months) -> 0 | D29: =IF(shooting_time=0,0,B29/shooting_time) -> 0 | E29: =IF(projects_year=0,0,B29/projects_year) -> 0 | F29: =IF((CHOOSE(regime_no,'05_Расчёт'!B4,'05_Расчёт'!C4,'05_Расчёт'!D4,'05_Расчёт'!E4,'05_Расчёт'!F4,'05_Расчёт'!G4,'05_Расчёт'!H4))=0,0,B29/(CHOOSE(regime_no,'05_Расчёт'!B4,'05_Расчёт'!C4,'05_Расчёт'!D4,'05_Расчёт'!E4,'05_Расчёт'!F4,'05_Расчёт'!G4,'05_Расчёт'!H4))) -> 0
A30: Аренда и коммунальные | B30: =var_workspace -> 67680 | C30: =IF(months=0,0,B30/months) -> 5640 | D30: =IF(shooting_time=0,0,B30/shooting_time) -> 312.46537 | E30: =IF(projects_year=0,0,B30/projects_year) -> 312.46537 | F30: =IF((CHOOSE(regime_no,'05_Расчёт'!B4,'05_Расчёт'!C4,'05_Расчёт'!D4,'05_Расчёт'!E4,'05_Расчёт'!F4,'05_Расчёт'!G4,'05_Расчёт'!H4))=0,0,B30/(CHOOSE(regime_no,'05_Расчёт'!B4,'05_Расчёт'!C4,'05_Расчёт'!D4,'05_Расчёт'!E4,'05_Расчёт'!F4,'05_Расчёт'!G4,'05_Расчёт'!H4))) -> 0.033135296
A31: ИТОГО переменные | B31: =variable_costs -> 283980 | C31: =IF(months=0,0,B31/months) -> 23665 | D31: =IF(shooting_time=0,0,B31/shooting_time) -> 1311.0803 | E31: =IF(projects_year=0,0,B31/projects_year) -> 1311.0803 | F31: =IF((CHOOSE(regime_no,'05_Расчёт'!B4,'05_Расчёт'!C4,'05_Расчёт'!D4,'05_Расчёт'!E4,'05_Расчёт'!F4,'05_Расчёт'!G4,'05_Расчёт'!H4))=0,0,B31/(CHOOSE(regime_no,'05_Расчёт'!B4,'05_Расчёт'!C4,'05_Расчёт'!D4,'05_Расчёт'!E4,'05_Расчёт'!F4,'05_Расчёт'!G4,'05_Расчёт'!H4))) -> 0.13903312
A33: 4 · ГОСУДАРСТВУ И БАНКУ
A34: Статья | B34: ₽/год | C34: ₽/месяц | D34: ₽/съём. час | E34: ₽/проект | F34: доля | G34: часов/год
A35: Налог и страховые взносы | B35: =CHOOSE(regime_no,'05_Расчёт'!B15,'05_Расчёт'!C15,'05_Расчёт'!D15,'05_Расчёт'!E15,'05_Расчёт'!F15,'05_Расчёт'!G15,'05_Расчёт'!H15) -> 102126.75 | C35: =IF(months=0,0,B35/months) -> 8510.5624 | D35: =IF(shooting_time=0,0,B35/shooting_time) -> 471.4993 | E35: =IF(projects_year=0,0,B35/projects_year) -> 471.4993 | F35: =IF((CHOOSE(regime_no,'05_Расчёт'!B4,'05_Расчёт'!C4,'05_Расчёт'!D4,'05_Расчёт'!E4,'05_Расчёт'!F4,'05_Расчёт'!G4,'05_Расчёт'!H4))=0,0,B35/(CHOOSE(regime_no,'05_Расчёт'!B4,'05_Расчёт'!C4,'05_Расчёт'!D4,'05_Расчёт'!E4,'05_Расчёт'!F4,'05_Расчёт'!G4,'05_Расчёт'!H4))) -> 0.05
A36: Эквайринг (комиссия банка) | B36: =(CHOOSE(regime_no,'05_Расчёт'!B4,'05_Расчёт'!C4,'05_Расчёт'!D4,'05_Расчёт'!E4,'05_Расчёт'!F4,'05_Расчёт'!G4,'05_Расчёт'!H4))*acquiring -> 55148.444 | C36: =IF(months=0,0,B36/months) -> 4595.7037 | D36: =IF(shooting_time=0,0,B36/shooting_time) -> 254.60962 | E36: =IF(projects_year=0,0,B36/projects_year) -> 254.60962 | F36: =IF((CHOOSE(regime_no,'05_Расчёт'!B4,'05_Расчёт'!C4,'05_Расчёт'!D4,'05_Расчёт'!E4,'05_Расчёт'!F4,'05_Расчёт'!G4,'05_Расчёт'!H4))=0,0,B36/(CHOOSE(regime_no,'05_Расчёт'!B4,'05_Расчёт'!C4,'05_Расчёт'!D4,'05_Расчёт'!E4,'05_Расчёт'!F4,'05_Расчёт'!G4,'05_Расчёт'!H4))) -> 0.027
A38: ВСЕГО = ВЫРУЧКА | B38: =CHOOSE(regime_no,'05_Расчёт'!B4,'05_Расчёт'!C4,'05_Расчёт'!D4,'05_Расчёт'!E4,'05_Расчёт'!F4,'05_Расчёт'!G4,'05_Расчёт'!H4) -> 2042535 | C38: =IF(months=0,0,B38/months) -> 170211.25 | D38: =IF(shooting_time=0,0,B38/shooting_time) -> 9429.986 | E38: =IF(projects_year=0,0,B38/projects_year) -> 9429.986 | F38: =1 -> 1
A39: Сверка: сумма всех статей | B39: =IF(ABS(B12+investment+variable_costs+B35+B36-B38)<1,"OK — сходится до рубля","РАСХОЖДЕНИЕ") -> OK — сходится до рубля
A41: 5 · ТРИ СЦЕНАРИЯ — сравните, где вы сейчас
A42: Сценарий | B42: Ставка часа | C42: Цена проекта | D42: Выручка/год | E42: На руки/год | F42: На руки/мес | G42: % от цели
A43: ВАША РАСЧЁТНАЯ — чтобы получать желаемое | B43: =(CHOOSE(regime_no,'05_Расчёт'!B4,'05_Расчёт'!C4,'05_Расчёт'!D4,'05_Расчёт'!E4,'05_Расчёт'!F4,'05_Расчёт'!G4,'05_Расчёт'!H4))/shooting_time -> 9429.986 | C43: =(CHOOSE(regime_no,'05_Расчёт'!B4,'05_Расчёт'!C4,'05_Расчёт'!D4,'05_Расчёт'!E4,'05_Расчёт'!F4,'05_Расчёт'!G4,'05_Расчёт'!H4))/projects_year -> 9429.986 | D43: =CHOOSE(regime_no,'05_Расчёт'!B4,'05_Расчёт'!C4,'05_Расчёт'!D4,'05_Расчёт'!E4,'05_Расчёт'!F4,'05_Расчёт'!G4,'05_Расчёт'!H4) -> 2042535 | E43: =target_income -> 1322592 | F43: =target_income/months -> 110216 | G43: =1 -> 1
A44: ВАША ТЕКУЩАЯ — по ней работаете сейчас | B44: =current_rate -> 6000 | C44: =current_rate*shooting_time/projects_year -> 6000 | D44: =current_rate*shooting_time -> 1299600 | E44: =(current_rate*shooting_time*(1-rate_current-acquiring)-total_costs) -> 636863.02 | F44: =(current_rate*shooting_time*(1-rate_current-acquiring)-total_costs)/months -> 53071.918 | G44: =(current_rate*shooting_time*(1-rate_current-acquiring)-total_costs)/target_income -> 0.48152644
A45: БЕЗУБЫТОЧНОСТЬ — работа в ноль | B45: =(CHOOSE(regime_no,'05_Расчёт'!B22,'05_Расчёт'!C22,'05_Расчёт'!D22,'05_Расчёт'!E22,'05_Расчёт'!F22,'05_Расчёт'!G22,'05_Расчёт'!H22))/shooting_time -> 2814.4394 | C45: =(CHOOSE(regime_no,'05_Расчёт'!B22,'05_Расчёт'!C22,'05_Расчёт'!D22,'05_Расчёт'!E22,'05_Расчёт'!F22,'05_Расчёт'!G22,'05_Расчёт'!H22))/projects_year -> 2814.4394 | D45: =CHOOSE(regime_no,'05_Расчёт'!B22,'05_Расчёт'!C22,'05_Расчёт'!D22,'05_Расчёт'!E22,'05_Расчёт'!F22,'05_Расчёт'!G22,'05_Расчёт'!H22) -> 609607.56 | E45: =0 -> 0 | F45: =0 -> 0 | G45: =0 -> 0
A47: Недополучено за год при текущей ставке | B47: =target_income-(current_rate*shooting_time*(1-rate_current-acquiring)-total_costs) -> 685728.98 | C47: это ваш вклад в чужой бизнес
...

Sheet 07_Интерфейс
A1: 07 · ИНТЕРФЕЙС — блоки и формы калькулятора
A3: Блок | B3: Раздел | C3: Заголовок | D3: Тип поля | E3: Формы | F3: Что задаёт | G3: Параметры в calc
A4: Block1 | B4: Section1 | C4: Ваш желаемый доход | D4: input_number | E4: — | F4: Сумма на руки в месяц | G4: income_month
A5: Block2 | B5: Section1 | C5: Текущая стоимость часа | D5: input_number | E5: — | F5: Для сравнения | G5: current_rate
A6: Block3 | B6: Section1 | C6: Минимальный заказ (часов) | D6: input_number | E6: — | F6: Базовый заказ: ниже не выезжаете | G6: shoot_duration
A7: Block3a | B7: Section1 | C7: Коэффициент обработки | D7: input_number | E7: — | F7: Часов обработки на 1 час съёмки | G7: post_ratio
A8: Block4 | B8: Section1 | C8: Режим налогообложения | D8: dropdown | E8: Form015, Form016 | F8: ПЕРЕКЛЮЧАТЕЛЬ, 7 вариантов | G8: regime
A9: Block5 | B9: Section1 | C9: Как мы считаем | D9: info_block | E9: — | F9: Пояснение | G9: —
A10: Block6 | B10: Section2 | C10: Съёмочное оборудование | D10: dynamic_table | E10: Form001 | F10: Список позиций | G10: dep_shoot
A11: Block7 | B11: Section2 | C11: Офисное оборудование | D11: dynamic_table | E11: Form002 | F11: Список позиций | G11: dep_office
A12: Block8 | B12: Section2 | C12: Программное обеспечение | D12: dynamic_tables | E12: Form003, Form004 | F12: Подписки и разовые | G12: var_software, dep_software
A13: Block9 | B13: Section2 | C13: Рабочее место | D13: dropdown + table | E13: Form005, Form013 | F13: ПЕРЕКЛЮЧАТЕЛЬ дом/аренда | G13: ws_mode, var_workspace, dep_workspace
A14: Block10 | B14: Section2 | C14: Проф. обучение | D14: input_extended | E14: Form006 | F14: Стоимость, месяцы обучения и срок окупаемости | G14: edu_opportunity, dep_education
... A23: Block18 | B23: Section5 | C23: Сравнение режимов | D23: report | E23: — | F23: Вывод | G23: 04_Расчёт

Sheet 08_UI
A1: 08 · UI-МАТРИЦА — точная карта интерфейса. Каждая строка = один элемент на экране
A2: Переносится в HTML построчно. Колонки: где стоит, что за поле, какая ширина, чем управляется, куда пишет значение.
A4: № | B4: Блок | C4: Раздел | D4: Заголовок / подпись | E4: Элемент | F4: Тип поля | G4: Ширина | H4: Значение по умолч. | I4: Ед. | J4: Форма | K4: Параметр (ID) | L4: Условие показа / блокировки
A5: 01 | B5: Block1 | C5: 1 · О вас | D5: Ваш желаемый доход | E5: самый важный параметр — на всю ширину
D6: Хочу получать на руки | E6: поле ввода | F6: input_number | G6: 52% + кнопка сброса | H6: 110 216 | I6: ₽/мес | J6: — | K6: income_month
A7: 02 | B7: Block4 + Block2 | C7: 1 · О вас | D7: Режим налогообложения и текущая ставка | E7: две колонки в одну строку
D8: Ваш режим налогообложения | E8: выпадающий список | F8: select | G8: 50% | H8: Самозанятый (НПД), средняя 5% | J8: Form015 | K8: regime | L8: 7 вариантов: НПД средняя/физ/юр, УСН 6, УСН 15, АУСН 8, АУСН 20
D9: Моя ставка сейчас | E9: поле ввода | F9: input_number | G9: 52% + кнопка сброса | H9: 6 000 | I9: ₽/час | J9: — | K9: current_rate | L9: необязательное; если 0 — блок «сколько теряете» скрыт
A10: 03 | B10: Block5 | C10: 1 · О вас | D10: Как мы считаем: | E10: информационный блок, полей нет
D11: Пояснительный текст | E11: текстовый блок | F11: info_block | G11: 100% | H11: Работа на себя должна делать вашу жизнь лучше, а не превращать её в бесконечную работу. Поэтому в расчётах Счётикс мы ориентируемся на нормы трудового законодательства РФ и производственный календарь — чтобы у вас оставались силы на творчество, развитие и жизнь вне работы. | J11: — | K11: — | L11: про отпуск, больничный, эффективные часы, почему час съёмки дороже часа работы
A12: 04 | B12: Block3 + Block3a | C12: 2 · Работа | D12: Как устроена ваша работа | E12: две колонки | H12: Время — ваш главный рабочий ресурс. Три плашки: «Всё рабочее время», «Невидимая нагрузка», «Честная стоимость часа». Каждая содержит крупную иконку и короткий тезис. Под заголовком: «Посчитаем время, которое обычно остаётся невидимым».
D13: Время на постпродакшн | E13: поле ввода | F13: input_number | G13: 52% + кнопка сброса | H13: 3 | I13: × | J13: — | K13: post_ratio
D14: Работа с клиентом (на один проект) | E14: поле ввода · блок можно исключить | F14: input_number | G14: 52% + кнопка сброса | H14: 1 | I14: ч | J14: Form012 | K14: client_time
D15: Поиск заказов | E15: поле ввода · блок можно исключить | F15: input_number | G15: 52% + кнопка сброса | H15: 2 | I15: ч/день | J15: Form009 | K15: promo_per_day
D16: Минимальный заказ (часов) | E16: поле ввода | F16: input_number | G16: 52% + кнопка сброса | H16: 2 | I16: ч | J16: — | K16: shoot_duration | L16: Активно всегда. По умолчанию 2 ч — типовой заказ
D17: Готовых кадров за 1 час | E17: поле ввода | F17: input_number | G17: 52% + кнопка сброса | H17: 2 | I17: ч | J17: — | K17: shoot_manual | L17: Дублирует shoot_duration в форме. Пользователь меняет свободно
D18: Шаг изменения | E18: поле ввода | F18: input_number | G18: 50% | H18: 0,5 | I18: ч | J18: — | K18: shoot_step | L18: Шаг стрелок в поле: 0,5 ч. Минимум 0,5 ч
A19: 05 | B19: Block14a | C19: 2 · Работа | D19: Резерв времени на простой и форс-мажоры | E19: галочка активирует поле
D20: Учитывать резерв времени на простой и форс-мажоры | E20: галочка | F20: checkbox | G20: 100% | H20: включена | J20: — | K20: fm_on
D21: Размер резерва | E21: поле ввода | F21: input_number | G21: 50% | H21: 5 | I21: % | J21: — | K21: fm_pct | L21: БЛОКИРУЕТСЯ, если галочка снята
A22: 06 | B22: Block6 | C22: 3 · Инвестиции | D22: Съёмочная техника | E22: динамическая таблица, 10 строк по умолчанию
D23: Не учитывать этот блок | E23: галочка | F23: checkbox | G23: авто | H23: снята | J23: Form001 | K23: use_Form001 | L23: при включении вся амортизация блока = 0
D24: Заголовки таблицы | E24: шапка | F24: table_head | G24: 100% | H24: Позиция · Стоимость ₽ · Срок лет · ₽/год | J24: Form001 | K24: —
D25: Canon EOS R6 Mark II Body | E25: строка таблицы | F25: table_row | G25: — | H25: 166 999 ₽ / 3 лет | L25: удаляется крестиком
D26: Canon RF 24–105mm f/4.0 L IS USM | E26: строка таблицы | F26: table_row | G26: — | H26: 130 999 ₽ / 5 лет | L26: удаляется крестиком
D27: Godox V1Pro C | E27: строка таблицы | F27: table_row | G27: — | H27: 36 990 ₽ / 5 лет | L27: удаляется крестиком
D28: Godox XPro II C | E28: строка таблицы | F28: table_row | G28: — | H28: 9 355 ₽ / 5 лет | L28: удаляется крестиком
D29: Аккумулятор LP-E6NH | E29: строка таблицы | F29: table_row | G29: — | H29: 12 978 ₽ / 3 лет | L29: удаляется крестиком
D30: SanDisk Extreme PRO 256 ГБ #1 | E30: строка таблицы | F30: table_row | G30: — | H30: 6 990 ₽ / 2 лет | L30: удаляется крестиком
D31: SanDisk Extreme PRO 256 ГБ #2 | E31: строка таблицы | F31: table_row | G31: — | H31: 6 990 ₽ / 2 лет | L31: удаляется крестиком
D32: Рюкзак Lowepro ProTactic | E32: строка таблицы | F32: table_row | G32: — | H32: 27 962 ₽ / 7 лет | L32: удаляется крестиком
D33: Godox RFT-05 отражатель | E33: строка таблицы | F33: table_row | G33: — | H33: 3 000 ₽ / 5 лет | L33: удаляется крестиком
D34: X-Rite ColorChecker | E34: строка таблицы | F34: table_row | G34: — | H34: 5 000 ₽ / 7 лет | L34: удаляется крестиком
D35: + Добавить позицию | E35: кнопка | F35: button_add | G35: авто | H35: — | J35: Form001 | K35: — | L35: добавляет пустую строку
D36: Итого амортизация | E36: строка итога | F36: calc_row | G36: 100% | H36: 137 893,32 | I36: ₽/год | J36: Form001 | K36: dep_shoot
A37: 07 | B37: Block7 | C37: 3 · Инвестиции | D37: Офисная техника | E37: динамическая таблица, 9 строк
D38: Не учитывать этот блок | E38: галочка | F38: checkbox | G38: авто | H38: снята | J38: Form002 | K38: use_Form002
D39: Заголовки таблицы | E39: шапка | F39: table_head | G39: 100% | H39: Позиция · Стоимость ₽ · Срок лет · ₽/год | J39: Form002 | K39: —
D40: Системный блок | E40: строка таблицы | F40: table_row | G40: — | H40: 180 000 ₽ / 5 лет | L40: удаляется крестиком
D41: Монитор ASUS ProArt | E41: строка таблицы | F41: table_row | G41: — | H41: 55 000 ₽ / 5 лет | L41: удаляется крестиком
...

Sheet 08c_Структура_отчёта
A1: 08c · СТРУКТУРА ОТЧЁТА — что и где показывается
A2: Порядок блоков сверху вниз, как в report.html. Колонка «Показатели» — какие цифры выводятся и по какой формуле. Колонка id — техническое имя контейнера в вёрстке, по нему цифра ищется в коде.
A4: ШАПКА И ГЛАВНЫЙ ЭКРАН
A5: № | B5: Блок | C5: Тип | D5: Показатели и формулы | E5: id в вёрстке
A6: — | B6: Шапка | C6: header | D6: Заголовок, подзаголовок, дата расчёта. Логотип справа | E6: rMeta
A7: — | B7: Зелёная плашка · ставка | C7: hero | D7: Крупно: ставка часа = revenue_full / shooting_time, округлена вверх до 500. В скобках точное значение. Под ней строка: фактическая стоимость часа = target_income / (net_time + idle_time) = 747 ₽. Три показателя в строку: · Ваш доход на руки = target_income / 12 · Всего расходов = (investment + variable_costs + налоги + эквайринг) / 12 · Общая выручка = revenue_full / 12 ПРОВЕРКА: доход + расходы = выручка | E7: hRate, hRateEx, hInc, hExp, hMon
A8: — | B8: Кнопка PDF | C8: button | D8: Печать. Имя файла: ГГГГ-ММ-ДД Счётикс для фотографа | E8: dlpdf
A9: — | B9: Условия труда по ТК | C9: cond | D9: 5/2 · 28 дней отпуска · 8 часов — константы календаря | E9: condGrid
A10: — | B10: Почему этому расчёту можно верить | C10: trust | D10: 4 аргумента доверия: считали от вашего дохода · учли всё время · нормы ТК РФ · 7 налоговых режимов | E10: —
A11: БЛОКИ ПОЛНОГО ОТЧЁТА
A12: № | B12: Блок | C12: Тип | D12: Показатели и формулы | E12: id в вёрстке
A13: 01 | B13: Как распределяется бюджет | C13: donut + легенда | D13: Кольцо: 15 сегментов, в центре ставка часа. Под кольцом текст: остаётся вам / идёт на расходы. ЛЕГЕНДА, три группы: 1. Ваш доход — 5 строк ролей: съёмка, обработка, клиент, продвижение, учёт 2. Не оплачивается — простой и форс-мажоры 3. Расходы и налоги — 9 строк: техника и ПО, обучение и сайт, рабочее место, реклама, подписки, аренда, банк, налоги, эквайринг Каждая строка: ₽ с часа · % · ₽/мес. Нулевые строки скрываются. ПРОВЕРКА: сумма всех строк = ставка часа | E13: dn1, dnSum, lg1
A14: 02 | B14: Как распределяется ваше время | C14: сетка 5×8 | D14: Рабочая неделя по слотам. Расшифровка по трём группам: фотограф / владелец бизнеса / не оплачивается | E14: wk, wknote, drows
A15: 03 | B15: Как считают обычно | C15: compare | D15: Формула: текущая ставка × часы съёмки в неделю × 4. Кажется / останется на самом деле + разница | E15: calcLine, inNaive, inReal, inNaiveTx | G15: УДАЛЁН из HTML 06.08.2026: не даёт пользователю полезной информации
A16: 04 | B16: Три сценария вашей работы | C16: 3 кольца | D16: ИДЕАЛЬНЫЙ (расчётная ставка) · РЕАЛЬНЫЙ (текущая) · В НОЛЬ (безубыточность). Для каждого: доход на руки, ставка часа, выручка в месяц. Ниже блок «При съёмке в ноль» + примечание о логистике | E16: dns, bRate, bProj
A17: 05 | B17: А если брать больше заказов | C17: scenario | D17: Съёмок в месяц, часов в день, рабочих дней, выходных при текущей ставке. Жёлтая плашка-предупреждение | E17: scn
