Workbook

Sheet Условные обозначения
A1: УСЛОВНЫЕ ОБОЗНАЧЕНИЯ — единый реестр понятий
A2: Тип: const — фиксированная аксиома из достоверного источника | calc — вычисляется формулой | default — предзаполнено, пользователь меняет | meta — служебное понятие реестра | ui — тип поля интерфейса
A4: A. МАРКЕРЫ ТИПОВ — служебные обозначения реестра
A5: № | B5: Наименование | C5: ID | D5: Тип | E5: Описание | F5: Формула / значение
A6: 1 | B6: Константа | C6: const | D6: meta | E6: Фиксированное значение-аксиома из достоверного источника (закон, производственный календарь, статистика). Пользователь не меняет | F6: 247 рабочих дня, 57 390 ₽
A7: 2 | B7: Формула | C7: calc | D7: meta | E7: Поле вычисляется из других значений. Пользователю показывается результат, ввод недоступен | F7: чистое время = (247−20−8)×7
A8: 3 | B8: Значение по умолчанию | C8: default | D8: meta | E8: Предзаполнено нашим значением (в т.ч. расчётным), пользователь может скорректировать | F8: желаемый доход 108 999 ₽
A9: 4 | B9: Служебное понятие | C9: meta | D9: meta | E9: Термин, описывающий устройство самого реестра, а не предметную область | F9: block, section, form
A10: 5 | B10: Тип поля интерфейса | C10: ui | D10: meta | E10: Обозначение способа ввода данных в калькуляторе | F10: input_number, dropdown
A11: 6 | B11: Скрытое поле | C11: hidden_field | D11: meta | E11: Считается автоматически, пользователю не показывается | F11: пересчёт покупки в ₽/год
A12: 7 | B12: Галочка «Не учитывать» | C12: exclude_flag | D12: meta | E12: Переключатель, исключающий блок или его часть из расчёта | F12: Block6–Block15
A13: B. ТИПЫ ПОЛЕЙ ИНТЕРФЕЙСА (значения столбца «Тип» на листе «Блоки»)
A14: № | B14: Наименование | C14: ID | D14: Тип | E14: Описание | F14: Формула / значение
A15: 8 | B15: Числовое поле | C15: input_number | D15: ui | E15: Одно поле для ввода числа | F15: Block1, Block3, Block13
A16: 9 | B16: Выпадающий список | C16: dropdown | D16: ui | E16: Готовый набор вариантов, выбирается один | F16: Block4, Block14
A17: 10 | B17: Расширенный ввод | C17: input_extended | D17: ui | E17: Несколько связанных полей, дающих один итог | F17: Block10 обучение
A18: 11 | B18: Переключатель + поле | C18: radio + input | D18: ui | E18: Выбор варианта и числовое поле, меняющее смысл | F18: Block12 сайт
A19: 12 | B19: Динамическая таблица | C19: dynamic_table | D19: ui | E19: Пользователь добавляет и удаляет строки | F19: Block6, Block7
A20: 13 | B20: Несколько таблиц | C20: dynamic_tables | D20: ui | E20: Блок содержит несколько независимых таблиц | F20: Block8 ПО
A21: 14 | B21: Список + таблица | C21: dropdown + dynamic_table | D21: ui | E21: Выбор варианта, под него появляется таблица | F21: Block9 рабочее место
A22: 15 | B22: Составной блок | C22: 2 parts | D22: ui | E22: Две разные формы в одном блоке: время и деньги | F22: Block11, Block15
A23: 16 | B23: Информационный блок | C23: info_block | D23: ui | E23: Только поясняющий текст, полей ввода нет | F23: Block5
A24: 17 | B24: Блок вывода | C24: report | D24: ui | E24: Итоговая страница с результатами, без формул | F24: Block16–Block18
A25: C. СТРУКТУРА РЕЕСТРА
A26: № | B26: Наименование | C26: ID | D26: Тип | E26: Описание | F26: Формула / значение
A27: 18 | B27: Реестр данных | C27: registry | D27: meta | E27: Рабочая книга со всеми параметрами, формулами и формами. Редактируется, видна изнутри | F27: эта книга
A28: 19 | B28: Калькулятор | C28: calculator | D28: meta | E28: Конечный продукт: тот же реестр в интерфейсе, формулы скрыты
A29: 20 | B29: Раздел | C29: section | D29: meta | E29: Логическое объединение блоков. Соответствует шагу интерфейса | F29: Section1–Section5
A30: 21 | B30: Блок | C30: block | D30: meta | E30: Совокупность данных, объединённых логически. Экран или его часть | F30: Block1–Block18
A31: 22 | B31: Форма | C31: form | D31: meta | E31: Таблица с данными для формы калькулятора. В блоке может быть несколько | F31: Form001–Form016
A32: 23 | B32: Поле | C32: item | D32: meta | E32: Поле для ввода данных пользователем
A33: 24 | B33: Вопрос | C33: question | D33: meta | E33: Формулировка рядом с полем — объясняет, что вписать
A34: 25 | B34: Отчёт | C34: report | D34: meta | E34: Итоговая страница с результатами для пользователя | F34: Section5
A35: 26 | B35: Пользователь | C35: user | D35: meta | E35: Человек, использующий калькулятор по назначению
A36: D. ВРЕМЯ — иерархия сверху вниз
A37: № | B37: Наименование | C37: ID | D37: Тип | E37: Описание | F37: Формула / значение
A38: 27 | B38: Рабочее время | C38: work_time | D38: const | E38: Время без выходных и праздников по производственному календарю РФ 2026 | F38: 247 дней × 8 ч = 1 976 ч
A39: 28 | B39: Чистое (эффективное) время | C39: net_time | D39: calc | E39: Рабочее время минус отпуск, больничный и 1 час в день на перерывы и второстепенные дела. ВЕРХНИЙ УРОВЕНЬ | F39: (247−20−8) × 7 = 1 533 ч/год
A40: 29 | B40: Операционное время | C40: side_time | D40: calc | E40: Обязанности вне проектов: продвижение и учёт. Клиенту напрямую не продаётся | F40: 438 + 12 = 450 ч/год
A41: 30 | B41: Профильное время | C41: core_time | D41: calc | E41: Работа по специальности: съёмка, постпродакшн, работа с клиентом | F41: 1 533 − 450 = 1 083 ч/год
...

Sheet Блоки
A1: СПЕЦИФИКАЦИЯ БЛОКОВ ИНТЕРФЕЙСА
A3: SECTION 1 — О ВАС И ВАШЕЙ РАБОТЕ
A4: ID | B4: Раздел | C4: H2 (Заголовок) | D4: H3 (Подзаголовок) | E4: Тип | F4: Формы_ID | G4: Описание под полем | H4: Исключаемый | I4: По умолч. | J4: Куда идёт в расчёт
A5: Block1 | B5: Section1 | C5: Желаемый доход | D5: Сколько хотите получать на руки ежемесячно | E5: input_number | F5: — | G5: По умолчанию — средняя номинальная зарплата по РФ, Росстат 2026 | H5: Нет | I5: 108 999 | J5: target_income → N
A6: Block2 | B6: Section1 | C6: Текущая стоимость часа | D6: Ваша текущая ставка — для сравнения | E6: input_number | F6: — | G6: Необязательное. Нужно для блока «Сколько вы теряете» | H6: Да | I6: 6 000 | J6: current_rate, в расчёт НЕ идёт
A7: Block3 | B7: Section1 | C7: Продолжительность съёмки | D7: Средняя длительность одной съёмки, часов | E7: input_number | F7: — | G7: Сложите часы съёмок за период и разделите на число съёмок | H7: Нет | I7: 7 ← было 0 | J7: S → проектное время
A8: Block3a | B8: Section1 | C8: Коэффициент обработки | D8: Сколько часов обработки на 1 час съёмки | E8: input_number | F8: — | G8: НОВЫЙ БЛОК. Без него проектное время не считается | H8: Нет | I8: 3 | J8: K → проектное время
A9: Block4 | B9: Section1 | C9: Ваш режим налогообложения | D9: — | E9: dropdown | F9: Form015, Form016 | G9: Если работаете и с юрлицами, и с физлицами — укажите доли выручки | H9: Нет | I9: УСН 6% | J9: ставка налога
A10: Block5 | B10: Section1 | C10: Как мы считаем | D10: Мы опираемся на нормы трудового законодательства РФ | E10: info_block | F10: — | G10: Про отпуск, больничный, эффективные часы. Ссылку на ст. 152 ТК убрать | H10: Нет | I10: — | J10: —
A12: SECTION 2 — ВАШИ ИНВЕСТИЦИИ В СВОЁ ДЕЛО (амортизируются)
A13: ID | B13: Раздел | C13: H2 (Заголовок) | D13: H3 (Подзаголовок) | E13: Тип | F13: Формы_ID | G13: Описание под полем | H13: Исключаемый | I13: По умолч. | J13: Куда идёт в расчёт
A14: Block6 | B14: Section2 | C14: Съёмочное оборудование | D14: Базовый комплект для каждой съёмки | E14: dynamic_table | F14: Form001 | G14: Актуальная рыночная стоимость; для снятых с производства — аналог. Разовую аренду не включать | H14: Да | I14: — | J14: investment → амортизация
A15: Block7 | B15: Section2 | C15: Офисное оборудование | D15: Для работы вне съёмочной площадки | E15: dynamic_table | F15: Form002 | G15: Аналогично Block6 | H15: Да | I15: — | J15: investment → амортизация
A16: Block8 | B16: Section2 | C16: Программное обеспечение | D16: Программы и сервисы | E16: dynamic_tables | F16: Form003, Form004 | G16: Form003 — подписки (переменные). Form004 — разовые покупки (амортизация) | H16: Да | I16: — | J16: Form003 → переменные, Form004 → амортизация
A17: Block9 | B17: Section2 | C17: Рабочее место | D17: Работаете из дома или арендуете? | E17: dropdown + dynamic_table | F17: Form005, Form013 | G17: Form013 — обустройство (амортизация). Form005 — содержание (переменные, по доле площади) | H17: Да | I17: — | J17: Form013 → амортизация, Form005 → переменные
A18: Block10 | B18: Section2 | C18: Проф. обучение | D18: — | E18: input_extended | F18: Form006 | G18: Стоимость курса, месяцев без дохода, срок амортизации. Упущенную выгоду можно отключить | H18: Да | I18: — | J18: investment → амортизация
A19: Block12 | B19: Section2 | C19: Создание сайта | D19: Сами делали (часы) или нанимали (₽)? | E19: radio + input | F19: Form014 | G19: ВНИМАНИЕ: вариант «сам» создаёт цикл. Формула ниже, в блоке «Особые случаи» | H19: Да | I19: нанимал, 70 000 | J19: investment → амортизация
A21: SECTION 3 — РЕГУЛЯРНЫЕ РАСХОДЫ
A22: ID | B22: Раздел | C22: H2 (Заголовок) | D22: H3 (Подзаголовок) | E22: Тип | F22: Формы_ID | G22: Описание под полем | H22: Исключаемый | I22: По умолч. | J22: Куда идёт в расчёт
A23: Block11 | B23: Section3 | C23: Поиск заказов (продвижение и реклама) | D23: — | E23: 2 parts | F23: Form009, Form010 | G23: Form009 — время (часов/день). Form010 — деньги (реклама, домен, хостинг). ПЕРЕНЕСЁН из Section2 | H23: Да | I23: 2 ч/день | J23: Form009 → promo_time, Form010 → переменные
A24: Block14 | B24: Section3 | C24: Учёт и планирование | D24: Сами ведёте или нанимаете бухгалтера? | E24: dropdown | F24: Form011 | G24: Взаимоисключающий выбор: либо часы, либо рубли. Оба сразу не учитываются | H24: Да | I24: бухгалтер 10 000/мес | J24: время ИЛИ переменные
A25: Block15 | B25: Section3 | C25: Банковские расходы | D25: — | E25: 2 parts | F25: Form007, Form008 | G25: Form007 — РКО и СМС (расход). Form008 — эквайринг (% с оборота, в знаменатель) | H25: Да | I25: 2,7% | J25: Form007 → переменные, Form008 → знаменатель
A27: SECTION 4 — ВРЕМЯ НА ПРОЕКТ (новый раздел)
A28: ID | B28: Раздел | C28: H2 (Заголовок) | D28: H3 (Подзаголовок) | E28: Тип | F28: Формы_ID | G28: Описание под полем | H28: Исключаемый | I28: По умолч. | J28: Куда идёт в расчёт
A29: Block13 | B29: Section4 | C29: Работа с клиентом | D29: Время на административную работу по одному проекту | E29: input_number | F29: Form012 | G29: ПЕРЕНЕСЁН из Section3: это время, а не расход | H29: Да | I29: 1 ч/проект | J29: client_time → проектное время
A31: SECTION 5 — РЕЗУЛЬТАТ (отсутствовал в спецификации)
A32: ID | B32: Раздел | C32: H2 (Заголовок) | D32: H3 (Подзаголовок) | E32: Тип | F32: Формы_ID | G32: Описание под полем | H32: Исключаемый | I32: По умолч. | J32: Куда идёт в расчёт
A33: Block16 | B33: Section5 | C33: Ваша ставка часа | D33: Сколько должен стоить час вашей съёмки | E33: report | F33: — | G33: real_rate по выбранному режиму + стоимость проекта | H33: Нет | I33: — | J33: вывод
A34: Block17 | B34: Section5 | C34: Сколько вы теряете | D34: Сравнение с текущей ставкой | E34: report | F34: — | G34: Работает только если заполнен Block2. Наивная vs полная ставка | H34: Да | I34: — | J34: вывод
A35: Block18 | B35: Section5 | C35: Сравнение режимов | D35: Какой режим выгоднее | E35: report | F35: — | G35: Шесть колонок, подсветка минимума. Предупреждения о лимитах НПД / НДС | H35: Нет | I35: — | J35: вывод
A38: СПИСОК ФОРМ (ошибки #ИМЯ? устранены — связи проставлены явно)
A39: Form_ID | B39: Блок_ID | C39: Наименование | D39: Что содержит | E39: Куда попадает
A40: Form001 | B40: Block6 | C40: Съёмочное оборудование | D40: позиция, стоимость, срок | E40: амортизация
A41: Form002 | B41: Block7 | C41: Офисное оборудование | D41: позиция, стоимость, срок | E41: амортизация
A42: Form003 | B42: Block8 | C42: ПО — подписки | D42: позиция, стоимость, период | E42: переменные
A43: Form004 | B43: Block8 | C43: ПО — разовые покупки | D43: позиция, стоимость, срок | E43: амортизация
A44: Form005 | B44: Block9 | C44: Рабочее место — содержание | D44: аренда, коммуналка, площади | E44: переменные (по доле)
A45: Form006 | B45: Block10 | C45: Проф. обучение | D45: курс, месяцев, срок, флаг упущенной выгоды | E45: амортизация
A46: Form007 | B46: Block15 | C46: Банк — регулярные | D46: РКО, СМС | E46: переменные
A47: Form008 | B47: Block15 | C47: Банк — эквайринг | D47: % и доля безнала | E47: знаменатель формулы
...

Sheet Формы
A1: ФОРМЫ — источники расходов
A3: Съёмочное оборудование, амортизация
A4: Позиция | B4: Стоимость, ₽ | C4: Срок, лет | D4: Амортизация ₽/год
A5: Canon EOS R6 Mark II | B5: 239999 | C5: 3 | D5: =IF(C5=0,0,B5/C5)
A6: Canon RF 24–105mm F4 L | B6: 159999 | C6: 5 | D6: =IF(C6=0,0,B6/C6)
A7: Godox V1Pro C | B7: 36990 | C7: 5 | D7: =IF(C7=0,0,B7/C7)
A8: Godox XPro II C | B8: 9355 | C8: 5 | D8: =IF(C8=0,0,B8/C8)
A9: Аккумулятор LP-E6NH | B9: 12978 | C9: 3 | D9: =IF(C9=0,0,B9/C9)
A10: SanDisk Extreme PRO 256 ГБ #1 | B10: 6990 | C10: 2 | D10: =IF(C10=0,0,B10/C10)
A11: SanDisk Extreme PRO 256 ГБ #2 | B11: 6990 | C11: 2 | D11: =IF(C11=0,0,B11/C11)
A12: Рюкзак Lowepro ProTactic | B12: 27962 | C12: 7 | D12: =IF(C12=0,0,B12/C12)
A13: Godox RFT-05 отражатель | B13: 3000 | C13: 5 | D13: =IF(C13=0,0,B13/C13)
A14: X-Rite ColorChecker | B14: 5000 | C14: 7 | D14: =IF(C14=0,0,B14/C14)
A15: ИТОГО, амортизация ₽/год | D15: =SUM(D5:D14)
A17: Офисное оборудование, амортизация
A18: Позиция | B18: Стоимость, ₽ | C18: Срок, лет | D18: Амортизация ₽/год
A19: Системный блок | B19: 180000 | C19: 5 | D19: =IF(C19=0,0,B19/C19)
A20: Монитор ASUS ProArt | B20: 55000 | C20: 5 | D20: =IF(C20=0,0,B20/C20)
A21: Calibrite ColorChecker | B21: 30000 | C21: 5 | D21: =IF(C21=0,0,B21/C21)
A22: Колонки Logitech Z207 | B22: 5000 | C22: 5 | D22: =IF(C22=0,0,B22/C22)
A23: Клавиатура Logitech K380 | B23: 3500 | C23: 7 | D23: =IF(C23=0,0,B23/C23)
A24: Мышь Logitech M650 | B24: 4000 | C24: 3 | D24: =IF(C24=0,0,B24/C24)
A25: Веб-камера Logitech Brio | B25: 15999 | C25: 5 | D25: =IF(C25=0,0,B25/C25)
A26: Микрофон FIFINE K669B | B26: 3500 | C26: 5 | D26: =IF(C26=0,0,B26/C26)
A27: Принтер Canon PIXMA G640 | B27: 29999 | C27: 5 | D27: =IF(C27=0,0,B27/C27)
A28: ИТОГО, амортизация ₽/год | D28: =SUM(D19:D27)
A30: ПО разовая покупка + рабочее место + обучение + сайт (амортизация)
A31: Позиция | B31: Стоимость, ₽ | C31: Срок, лет | D31: Амортизация ₽/год
A32: Retouch4me Heal | B32: 6900 | C32: 3 | D32: =IF(C32=0,0,B32/C32)
A33: Retouch4me Dodge & Burn | B33: 6900 | C33: 3 | D33: =IF(C33=0,0,B33/C33)
A34: Retouch4me Fabric | B34: 6900 | C34: 3 | D34: =IF(C34=0,0,B34/C34)
A35: Retouch4me Clean Backdrop | B35: 6900 | C35: 3 | D35: =IF(C35=0,0,B35/C35)
A36: Retouch4me Dust | B36: 6900 | C36: 3 | D36: =IF(C36=0,0,B36/C36)
A37: Мебель | B37: 35000 | C37: 7 | D37: =IF(C37=0,0,B37/C37)
A38: Косметический ремонт | B38: 30000 | C38: 7 | D38: =IF(C38=0,0,B38/C38)
A39: Создание сайта (нанимал специалиста) | B39: 70000 | C39: 7 | D39: =IF(C39=0,0,B39/C39)
A40: Курс по фотографии (стоимость) | B40: 80000 | C40: 7 | D40: =(B40+B42*B41*Расчёт!$C$47)/C40 | E40: упущенная выгода = мес × желаемый доход/мес
A41: └ месяцев обучения (упущенная выгода) | B41: 4
A42: └ учитывать упущенную выгоду (1/0) | B42: 1
A43: ИТОГО, амортизация ₽/год | D43: =SUM(D32:D42)
...

Sheet Данные из форм
A1: ДАННЫЕ ИЗ ФОРМ — сводка (всё тянется ссылками, вручную не вводить)
A3: 1. ИНВЕСТИЦИИ (амортизация), ₽/год
A4: Источник | B4: ₽/год
A5: Съёмочное оборудование | B5: =Формы!D15
A6: Офисное оборудование | B6: =Формы!D28
A7: ПО, рабочее место, обучение, сайт | B7: =Формы!D43
A8: ИТОГО инвестиции, ₽/год | B8: =SUM(B5:B7)
A10: 2. ПЕРЕМЕННЫЕ РАСХОДЫ, ₽/год
A11: Источник | B11: ₽/год | C11: Примечание
A12: Все регулярные платежи (ПО, банк, реклама, бухгалтер) | B12: =Формы!D67-Формы!D66 | C12: включая бухгалтера 120 000
A13: Рабочее место (доля кабинета) | B13: =Формы!D66
A14: ИТОГО переменные, ₽/год | B14: =SUM(B12:B13)
A15: ВСЕГО РАСХОДОВ (C), ₽/год | B15: ='Данные из форм'!$B$8+'Данные из форм'!$B$14
A17: 3. ВРЕМЕННЫЕ ЗАТРАТЫ, часов/год
A18: Источник | B18: Часов/год | C18: Примечание
A19: Продвижение (соцсети и пр.) | B19: =Формы!B74*Расчёт!$C$13 | C19: час/день × чистых рабочих дней
A20: Учёт и планирование | B20: =Формы!B75*Расчёт!$C$7 | C20: был потерян в исходной сводке
A21: ИТОГО операционное время, час/год | B21: =SUM(B19:B20)
A22: Работа с клиентом, час/проект | B22: =Формы!B76 | C22: НЕ суммируется сюда — входит в проектное время
A24: 4. СТАВКИ ОТ ОБОРОТА, %
A25: Источник | B25: Ставка | C25: Идёт в знаменатель?
A26: Эквайринг (комиссия с оборота) | B26: =Формы!B70*Формы!B71 | C26: ДА — общая для всех режимов
A27: Ставка налогового режима | B27: — | C27: НЕ сводится сюда — своя в каждой колонке
A29: 5. ПОЧЕМУ «ОБЩАЯ ПРОЦЕНТНАЯ СТАВКА 7,70» БЫЛА НЕВЕРНОЙ
A30: В исходной сводке столбец «% ставка (от оборота)» содержал 2,70 и 5,00, а итог 7,70 = их сумма.
A31: 2,70 — эквайринг. 5,00 — «Самозанятый (НПД), средняя ставка». Отсюда и бралась «Общая процентная ставка».
A33: Три проблемы:
A35: а) Ставки 5% в НПД не существует. Есть 4% (с физлицами) и 6% (с юрлицами). «Средняя» — выдуманная величина:
A36: при реальной структуре клиентов нужно считать взвешенно, а лучше — двумя отдельными колонками.
A38: б) Смешаны разные сущности. Эквайринг — комиссия банка, она есть на ЛЮБОМ режиме. Налог — своя ставка
A39: в каждой колонке. Их нельзя схлопывать в одно число: получается «ставка», которая не соответствует
A40: ни одному реальному режиму.
A42: в) Для ИП сложение вообще не работает. Складывать проценты допустимо, только когда ОБЕ величины —
A43: чистый процент от оборота. Это верно для НПД (нет взносов). Но на УСН есть фикс. взнос 57 390 ₽,
A44: который ВЫЧИТАЕТСЯ из налога, и допвзнос 1% с базы сверх 300 000 — это не процент от оборота.
... A57: (меньший доход, где фикс. взнос доминирует) ошибка вырастает в разы.

Sheet Расчёт
A1: КАЛЬКУЛЯТОР СТОИМОСТИ ЧАСА — соло-специалист, 2026
A3: 1. КАЛЕНДАРЬ
A4: const | B4: Рабочих дней в году (произв. календарь РФ 2026) | C4: 247
A5: const | B5: Рабочих дней в неделю | C5: 5
A6: const | B6: Месяцев в году | C6: 12
A7: const | B7: Кварталов в году | C7: 4
A8: const | B8: Отпуск, рабочих дней | C8: 20
A9: const | B9: Больничный, рабочих дней | C9: 8
A10: const | B10: Чистых (эффективных) часов в день | C10: 7
A12: 2. ЧИСТОЕ РАБОЧЕЕ ВРЕМЯ
A13: calc | B13: Чистое рабочее время, дней/год | C13: =$C$4-$C$8-$C$9
A14: calc | B14: Чистое рабочее время, часов/год | C14: =$C$13*$C$10
A15: calc | B15: Чистое рабочее время, недель/год | C15: =$C$13/$C$5
A16: calc | B16: Чистое рабочее время, часов/месяц | C16: =$C$14/$C$6
A17: calc | B17: Чистое рабочее время, часов/неделю | C17: =$C$14/$C$15
A19: 3. СТРУКТУРА ВРЕМЕНИ
A20: calc | B20: Время на продвижение, час/год | C20: ='Данные из форм'!$B$21-Расчёт!$C$22
A21: calc | B21: Время на продвижение, час/мес | C21: =$C$20/$C$6
A22: calc | B22: Учёт и планирование, час/год | C22: =Формы!$B$75*$C$7
A23: calc | B23: Операционное время, час/год (из сводки) | C23: ='Данные из форм'!$B$21 | E23: продвижение + учёт
A24: calc | B24: Операционное время, час/мес | C24: =$C$23/$C$6
A25: calc | B25: Операционное время, час/неделю | C25: =$C$23/$C$15
A26: calc | B26: Профильное время, час/год | C26: =$C$14-$C$23
A27: calc | B27: Профильное время, час/мес | C27: =$C$26/$C$6
A28: calc | B28: Профильное время, час/неделю | C28: =$C$26/$C$15
A30: 4. ПРОЕКТ
A31: default | B31: Съёмочных часов на 1 проект | C31: 7
A32: default | B32: Коэффициент обработки (ч обработки на 1 ч съёмки) | C32: 3
A33: calc | B33: Проектное время, час/проект | C33: =$C$31*(1+$C$32)+'Данные из форм'!$B$22
A34: calc | B34: Проектов в год | C34: =IF($C$33=0,0,$C$26/$C$33)
A35: calc | B35: Проектов в месяц | C35: =$C$34/$C$6
A36: calc | B36: Проектов в неделю | C36: =$C$34/$C$15
A37: calc | B37: Съёмочное время, час/год | C37: =$C$34*$C$31
A38: calc | B38: Съёмочное время, час/мес | C38: =$C$37/$C$6
A39: calc | B39: Съёмочное время, час/неделю | C39: =$C$37/$C$15
A40: calc | B40: Операционное время на час съёмки | C40: =IF($C$37=0,0,$C$23/$C$37)
A42: 5. ДОХОД И РАСХОДЫ (из листа «Формы»)
A43: calc | B43: Амортизация, ₽/год (из сводки) | C43: ='Данные из форм'!$B$8
A44: calc | B44: Переменные расходы, ₽/год (из сводки) | C44: ='Данные из форм'!$B$14
A45: calc | B45: Всего расходов (без эквайринга), ₽/год | C45: =$C$43+$C$44
...
